5:return {{["x"] = 0, ["y"] = 0, ["z"] = 0, ["name"] = "default:dirt_with_grass", ["param1"] = 28}, {["x"] = 0, ["y"] = 0, ["z"] = 1, ["name"] = "default:dirt_with_grass", ["param1"] = 28}, {["x"] = 0, ["y"] = 0, ["z"] = 2, ["name"] = "default:dirt_with_grass", ["param1"] = 28}, {["x"] = 0, ["y"] = 0, ["z"] = 3, ["name"] = "default:dirt_with_grass", ["param1"] = 28}, {["x"] = 0, ["y"] = 0, ["z"] = 4, ["name"] = "default:dirt_with_grass", ["param1"] = 28}, {["x"] = 0, ["y"] = 0, ["z"] = 5, ["name"] = "default:dirt_with_grass", ["param1"] = 28}, {["x"] = 0, ["y"] = 0, ["z"] = 6, ["name"] = "default:dirt_with_grass", ["param1"] = 28}, {["x"] = 0, ["y"] = 0, ["z"] = 7, ["name"] = "default:dirt_with_grass", ["param1"] = 28}, {["x"] = 0, ["y"] = 0, ["z"] = 8, ["name"] = "default:dirt_with_grass", ["param1"] = 28}, {["x"] = 0, ["y"] = 0, ["z"] = 9, ["name"] = "default:dirt_with_grass", ["param1"] = 28}, {["x"] = 0, ["y"] = 0, ["z"] = 10, ["name"] = "default:dirt_with_grass", ["param1"] = 28}, {["x"] = 0, ["y"] = 0, ["z"] = 11, ["name"] = "default:dirt_with_grass", ["param1"] = 28}, {["x"] = 0, ["y"] = 0, ["z"] = 12, ["name"] = "default:dirt_with_grass", ["param1"] = 28}, {["x"] = 0, ["y"] = 0, ["z"] = 13, ["name"] = "default:dirt_with_grass", ["param1"] = 28}, {["x"] = 0, ["y"] = 0, ["z"] = 14, ["name"] = "default:dirt_with_grass", ["param1"] = 28}, {["x"] = 0, ["y"] = 0, ["z"] = 15, ["name"] = "default:dirt_with_grass", ["param1"] = 28}, {["x"] = 0, ["y"] = 0, ["z"] = 16, ["name"] = "default:dirt_with_grass", ["param1"] = 28}, {["x"] = 0, ["y"] = 0, ["z"] = 17, ["name"] = "default:dirt_with_grass", ["param1"] = 28}, {["x"] = 0, ["y"] = 0, ["z"] = 18, ["name"] = "default:dirt_with_grass", ["param1"] = 28}, {["x"] = 0, ["y"] = 0, ["z"] = 19, ["name"] = "default:dirt_with_grass", ["param1"] = 28}, {["x"] = 0, ["y"] = 0, ["z"] = 20, ["name"] = "default:dirt_with_grass", ["param1"] = 28}, {["x"] = 0, ["y"] = 0, ["z"] = 21, ["name"] = "default:dirt_with_grass", ["param1"] = 28}, {["x"] = 0, ["y"] = 0, ["z"] = 22, ["name"] = "default:dirt_with_grass", ["param1"] = 28}, {["x"] = 0, ["y"] = 0, ["z"] = 23, ["name"] = "default:dirt_with_grass", ["param1"] = 28}, {["x"] = 0, ["y"] = 0, ["z"] = 24, ["name"] = "default:dirt_with_grass", ["param1"] = 28}, {["x"] = 0, ["y"] = 0, ["z"] = 25, ["name"] = "default:dirt_with_grass", ["param1"] = 28}, {["x"] = 0, ["y"] = 0, ["z"] = 26, ["name"] = "default:dirt_with_grass", ["param1"] = 28}, {["x"] = 0, ["y"] = 0, ["z"] = 27, ["name"] = "default:dirt_with_grass", ["param1"] = 28}, {["x"] = 0, ["y"] = 0, ["z"] = 28, ["name"] = "default:dirt_with_grass", ["param1"] = 28}, {["x"] = 0, ["y"] = 0, ["z"] = 29, ["name"] = "default:dirt_with_grass", ["param1"] = 28}, {["x"] = 0, ["y"] = 0, ["z"] = 30, ["name"] = "default:dirt_with_grass", ["param1"] = 28}, {["x"] = 0, ["y"] = 0, ["z"] = 31, ["name"] = "default:dirt_with_grass", ["param1"] = 28}, {["x"] = 0, ["y"] = 0, ["z"] = 32, ["name"] = "default:dirt_with_grass", ["param1"] = 28}, {["x"] = 0, ["y"] = 0, ["z"] = 33, ["name"] = "default:dirt_with_grass", ["param1"] = 28}, {["x"] = 0, ["y"] = 0, ["z"] = 34, ["name"] = "default:dirt_with_grass", ["param1"] = 28}, {["x"] = 0, ["y"] = 0, ["z"] = 35, ["name"] = "default:dirt_with_grass", ["param1"] = 28}, {["x"] = 0, ["y"] = 0, ["z"] = 36, ["name"] = "default:dirt_with_grass", ["param1"] = 28}, {["x"] = 0, ["y"] = 0, ["z"] = 37, ["name"] = "default:dirt_with_grass", ["param1"] = 28}, {["x"] = 0, ["y"] = 0, ["z"] = 38, ["name"] = "default:dirt_with_grass", ["param1"] = 28}, {["x"] = 0, ["y"] = 0, ["z"] = 39, ["name"] = "default:dirt_with_grass", ["param1"] = 28}, {["x"] = 0, ["y"] = 0, ["z"] = 40, ["name"] = "default:dirt_with_grass", ["param1"] = 28}, {["x"] = 0, ["y"] = 0, ["z"] = 41, ["name"] = "default:dirt_with_grass", ["param1"] = 28}, {["x"] = 0, ["y"] = 0, ["z"] = 42, ["name"] = "default:dirt_with_grass", ["param1"] = 28}, {["x"] = 0, ["y"] = 0, ["z"] = 43, ["name"] = "default:dirt_with_grass", ["param1"] = 28}, {["x"] = 0, ["y"] = 0, ["z"] = 44, ["name"] = "default:dirt_with_grass", ["param1"] = 28}, {["x"] = 0, ["y"] = 0, ["z"] = 45, ["name"] = "default:dirt_with_grass", ["param1"] = 28}, {["x"] = 0, ["y"] = 0, ["z"] = 46, ["name"] = "default:dirt_with_grass", ["param1"] = 28}, {["x"] = 0, ["y"] = 0, ["z"] = 47, ["name"] = "default:dirt_with_grass", ["param1"] = 28}, {["x"] = 0, ["y"] = 0, ["z"] = 48, ["name"] = "default:dirt_with_grass", ["param1"] = 28}, {["x"] = 0, ["y"] = 0, ["z"] = 49, ["name"] = "default:dirt_with_grass", ["param1"] = 28}, {["x"] = 0, ["y"] = 0, ["z"] = 50, ["name"] = "default:dirt_with_grass", ["param1"] = 28}, {["x"] = 0, ["y"] = 0, ["z"] = 51, ["name"] = "default:dirt_with_grass", ["param1"] = 28}, {["x"] = 0, ["y"] = 0, ["z"] = 52, ["name"] = "default:dirt_with_grass", ["param1"] = 28}, {["x"] = 0, ["y"] = 0, ["z"] = 53, ["name"] = "default:dirt_with_grass", ["param1"] = 28}, {["x"] = 0, ["y"] = 0, ["z"] = 54, ["name"] = "default:dirt_with_grass", ["param1"] = 28}, {["x"] = 0, ["y"] = 1, ["z"] = 21, ["param2"] = 1, ["name"] = "angledwalls:angled_walldesertstone", ["param1"] = 30}, {["x"] = 0, ["y"] = 1, ["z"] = 22, ["param2"] = 2, ["name"] = "angledwalls:angled_walldesertstone", ["param1"] = 30}, {["x"] = 0, ["y"] = 1, ["z"] = 31, ["param2"] = 1, ["name"] = "angledwalls:angled_walldesertstone", ["param1"] = 30}, {["x"] = 0, ["y"] = 1, ["z"] = 32, ["param2"] = 2, ["name"] = "angledwalls:angled_walldesertstone", ["param1"] = 30}, {["x"] = 0, ["y"] = 2, ["z"] = 21, ["param2"] = 1, ["name"] = "default:pine_needles", ["param1"] = 46}, {["x"] = 0, ["y"] = 2, ["z"] = 22, ["param2"] = 1, ["name"] = "default:pine_needles", ["param1"] = 46}, {["x"] = 0, ["y"] = 2, ["z"] = 31, ["param2"] = 1, ["name"] = "default:pine_needles", ["param1"] = 46}, {["x"] = 0, ["y"] = 2, ["z"] = 32, ["param2"] = 1, ["name"] = "default:pine_needles", ["param1"] = 46}, {["x"] = 0, ["y"] = 3, ["z"] = 21, ["param2"] = 1, ["name"] = "default:pine_needles", ["param1"] = 46}, {["x"] = 0, ["y"] = 3, ["z"] = 22, ["param2"] = 1, ["name"] = "default:pine_needles", ["param1"] = 46}, {["x"] = 0, ["y"] = 3, ["z"] = 31, ["param2"] = 1, ["name"] = "default:pine_needles", ["param1"] = 46}, {["x"] = 0, ["y"] = 3, ["z"] = 32, ["param2"] = 1, ["name"] = "default:pine_needles", ["param1"] = 46}, {["x"] = 0, ["y"] = 4, ["z"] = 22, ["param2"] = 1, ["name"] = "default:pine_needles", ["param1"] = 46}, {["x"] = 0, ["y"] = 4, ["z"] = 31, ["param2"] = 1, ["name"] = "default:pine_needles", ["param1"] = 46}, {["x"] = 1, ["y"] = 0, ["z"] = 0, ["name"] = "default:dirt_with_grass", ["param1"] = 28}, {["x"] = 1, ["y"] = 0, ["z"] = 1, ["name"] = "default:dirt_with_grass", ["param1"] = 28}, {["x"] = 1, ["y"] = 0, ["z"] = 2, ["name"] = "default:dirt_with_grass", ["param1"] = 28}, {["x"] = 1, ["y"] = 0, ["z"] = 3, ["name"] = "default:dirt_with_grass", ["param1"] = 28}, {["x"] = 1, ["y"] = 0, ["z"] = 4, ["name"] = "default:dirt_with_grass", ["param1"] = 28}, {["x"] = 1, ["y"] = 0, ["z"] = 5, ["name"] = "default:dirt_with_grass", ["param1"] = 28}, {["x"] = 1, ["y"] = 0, ["z"] = 6, ["name"] = "default:dirt_with_grass"}, {["x"] = 1, ["y"] = 0, ["z"] = 7, ["name"] = "default:dirt_with_grass", ["param1"] = 28}, {["x"] = 1, ["y"] = 0, ["z"] = 8, ["name"] = "default:dirt_with_grass", ["param1"] = 28}, {["x"] = 1, ["y"] = 0, ["z"] = 9, ["name"] = "default:dirt_with_grass", ["param1"] = 28}, {["x"] = 1, ["y"] = 0, ["z"] = 10, ["name"] = "default:dirt_with_grass", ["param1"] = 28}, {["x"] = 1, ["y"] = 0, ["z"] = 11, ["name"] = "default:dirt_with_grass", ["param1"] = 28}, {["x"] = 1, ["y"] = 0, ["z"] = 12, ["name"] = "default:dirt_with_grass", ["param1"] = 28}, {["x"] = 1, ["y"] = 0, ["z"] = 13, ["name"] = "default:dirt_with_grass", ["param1"] = 28}, {["x"] = 1, ["y"] = 0, ["z"] = 14, ["name"] = "default:dirt_with_grass", ["param1"] = 28}, {["x"] = 1, ["y"] = 0, ["z"] = 15, ["name"] = "default:dirt_with_grass", ["param1"] = 28}, {["x"] = 1, ["y"] = 0, ["z"] = 16, ["name"] = "default:dirt_with_grass", ["param1"] = 28}, {["x"] = 1, ["y"] = 0, ["z"] = 17, ["name"] = "default:dirt_with_grass", ["param1"] = 28}, {["x"] = 1, ["y"] = 0, ["z"] = 18, ["name"] = "default:dirt_with_grass", ["param1"] = 28}, {["x"] = 1, ["y"] = 0, ["z"] = 19, ["name"] = "default:dirt_with_grass", ["param1"] = 28}, {["x"] = 1, ["y"] = 0, ["z"] = 20, ["name"] = "default:dirt_with_grass", ["param1"] = 28}, {["x"] = 1, ["y"] = 0, ["z"] = 21, ["name"] = "default:dirt_with_grass", ["param1"] = 28}, {["x"] = 1, ["y"] = 0, ["z"] = 22, ["name"] = "default:dirt_with_grass", ["param1"] = 28}, {["x"] = 1, ["y"] = 0, ["z"] = 23, ["name"] = "default:dirt_with_grass", ["param1"] = 28}, {["x"] = 1, ["y"] = 0, ["z"] = 24, ["name"] = "default:dirt_with_grass", ["param1"] = 28}, {["x"] = 1, ["y"] = 0, ["z"] = 25, ["name"] = "default:dirt_with_grass", ["param1"] = 28}, {["x"] = 1, ["y"] = 0, ["z"] = 26, ["name"] = "default:dirt_with_grass", ["param1"] = 28}, {["x"] = 1, ["y"] = 0, ["z"] = 27, ["name"] = "default:dirt_with_grass", ["param1"] = 28}, {["x"] = 1, ["y"] = 0, ["z"] = 28, ["name"] = "default:dirt_with_grass", ["param1"] = 28}, {["x"] = 1, ["y"] = 0, ["z"] = 29, ["name"] = "default:dirt_with_grass", ["param1"] = 28}, {["x"] = 1, ["y"] = 0, ["z"] = 30, ["name"] = "default:dirt_with_grass", ["param1"] = 28}, {["x"] = 1, ["y"] = 0, ["z"] = 31, ["name"] = "default:dirt_with_grass", ["param1"] = 28}, {["x"] = 1, ["y"] = 0, ["z"] = 32, ["name"] = "default:dirt_with_grass", ["param1"] = 28}, {["x"] = 1, ["y"] = 0, ["z"] = 33, ["name"] = "default:dirt_with_grass", ["param1"] = 28}, {["x"] = 1, ["y"] = 0, ["z"] = 34, ["name"] = "default:dirt_with_grass", ["param1"] = 28}, {["x"] = 1, ["y"] = 0, ["z"] = 35, ["name"] = "default:dirt_with_grass", ["param1"] = 28}, {["x"] = 1, ["y"] = 0, ["z"] = 36, ["name"] = "default:dirt_with_grass", ["param1"] = 28}, {["x"] = 1, ["y"] = 0, ["z"] = 37, ["name"] = "default:dirt_with_grass", ["param1"] = 28}, {["x"] = 1, ["y"] = 0, ["z"] = 38, ["name"] = "default:dirt_with_grass", ["param1"] = 28}, {["x"] = 1, ["y"] = 0, ["z"] = 39, ["name"] = "default:dirt_with_grass", ["param1"] = 28}, {["x"] = 1, ["y"] = 0, ["z"] = 40, ["name"] = "default:dirt_with_grass", ["param1"] = 28}, {["x"] = 1, ["y"] = 0, ["z"] = 41, ["name"] = "default:dirt_with_grass", ["param1"] = 28}, {["x"] = 1, ["y"] = 0, ["z"] = 42, ["name"] = "default:dirt_with_grass", ["param1"] = 28}, {["x"] = 1, ["y"] = 0, ["z"] = 43, ["name"] = "default:dirt_with_grass", ["param1"] = 28}, {["x"] = 1, ["y"] = 0, ["z"] = 44, ["name"] = "default:dirt_with_grass", ["param1"] = 28}, {["x"] = 1, ["y"] = 0, ["z"] = 45, ["name"] = "default:dirt_with_grass", ["param1"] = 28}, {["x"] = 1, ["y"] = 0, ["z"] = 46, ["name"] = "default:dirt_with_grass", ["param1"] = 28}, {["x"] = 1, ["y"] = 0, ["z"] = 47, ["name"] = "default:dirt_with_grass", ["param1"] = 28}, {["x"] = 1, ["y"] = 0, ["z"] = 48, ["name"] = "default:dirt_with_grass", ["param1"] = 28}, {["x"] = 1, ["y"] = 0, ["z"] = 49, ["name"] = "default:dirt_with_grass", ["param1"] = 28}, {["x"] = 1, ["y"] = 0, ["z"] = 50, ["name"] = "default:dirt_with_grass", ["param1"] = 28}, {["x"] = 1, ["y"] = 0, ["z"] = 51, ["name"] = "default:dirt_with_grass", ["param1"] = 28}, {["x"] = 1, ["y"] = 0, ["z"] = 52, ["name"] = "default:dirt_with_grass", ["param1"] = 28}, {["x"] = 1, ["y"] = 0, ["z"] = 53, ["name"] = "default:dirt_with_grass", ["param1"] = 28}, {["x"] = 1, ["y"] = 0, ["z"] = 54, ["name"] = "default:dirt_with_grass", ["param1"] = 28}, {["x"] = 1, ["y"] = 1, ["z"] = 21, ["name"] = "angledwalls:angled_walldesertstone", ["param1"] = 46}, {["x"] = 1, ["y"] = 1, ["z"] = 22, ["param2"] = 3, ["name"] = "angledwalls:angled_walldesertstone", ["param1"] = 45}, {["x"] = 1, ["y"] = 1, ["z"] = 31, ["name"] = "angledwalls:angled_walldesertstone", ["param1"] = 45}, {["x"] = 1, ["y"] = 1, ["z"] = 32, ["param2"] = 3, ["name"] = "angledwalls:angled_walldesertstone", ["param1"] = 46}, {["x"] = 1, ["y"] = 2, ["z"] = 21, ["param2"] = 1, ["name"] = "default:pine_needles", ["param1"] = 62}, {["x"] = 1, ["y"] = 2, ["z"] = 22, ["param2"] = 1, ["name"] = "default:pine_needles", ["param1"] = 61}, {["x"] = 1, ["y"] = 2, ["z"] = 31, ["param2"] = 1, ["name"] = "default:pine_needles", ["param1"] = 61}, {["x"] = 1, ["y"] = 2, ["z"] = 32, ["param2"] = 1, ["name"] = "default:pine_needles", ["param1"] = 62}, {["x"] = 1, ["y"] = 3, ["z"] = 21, ["param2"] = 1, ["name"] = "default:pine_needles", ["param1"] = 62}, {["x"] = 1, ["y"] = 3, ["z"] = 22, ["param2"] = 1, ["name"] = "default:pine_needles", ["param1"] = 61}, {["x"] = 1, ["y"] = 3, ["z"] = 31, ["param2"] = 1, ["name"] = "default:pine_needles", ["param1"] = 61}, {["x"] = 1, ["y"] = 3, ["z"] = 32, ["param2"] = 1, ["name"] = "default:pine_needles", ["param1"] = 62}, {["x"] = 1, ["y"] = 4, ["z"] = 21, ["param2"] = 1, ["name"] = "default:pine_needles", ["param1"] = 62}, {["x"] = 1, ["y"] = 4, ["z"] = 22, ["param2"] = 1, ["name"] = "default:pine_needles", ["param1"] = 61}, {["x"] = 1, ["y"] = 4, ["z"] = 31, ["param2"] = 1, ["name"] = "default:pine_needles", ["param1"] = 61}, {["x"] = 1, ["y"] = 4, ["z"] = 32, ["param2"] = 1, ["name"] = "default:pine_needles", ["param1"] = 62}, {["x"] = 1, ["y"] = 5, ["z"] = 21, ["param2"] = 1, ["name"] = "default:pine_needles", ["param1"] = 62}, {["x"] = 1, ["y"] = 5, ["z"] = 22, ["param2"] = 1, ["name"] = "default:pine_needles", ["param1"] = 62}, {["x"] = 1, ["y"] = 5, ["z"] = 31, ["param2"] = 1, ["name"] = "default:pine_needles", ["param1"] = 62}, {["x"] = 1, ["y"] = 5, ["z"] = 32, ["param2"] = 1, ["name"] = "default:pine_needles", ["param1"] = 62}, {["x"] = 1, ["y"] = 6, ["z"] = 22, ["param2"] = 1, ["name"] = "default:pine_needles", ["param1"] = 62}, {["x"] = 1, ["y"] = 6, ["z"] = 31, ["param2"] = 1, ["name"] = "default:pine_needles", ["param1"] = 62}, {["x"] = 1, ["y"] = 7, ["z"] = 23, ["param2"] = 9, ["name"] = "cblocks:micro_stonebrick_white", ["param1"] = 30}, {["x"] = 1, ["y"] = 7, ["z"] = 24, ["param2"] = 23, ["name"] = "cblocks:panel_stonebrick_white", ["param1"] = 14}, {["x"] = 1, ["y"] = 7, ["z"] = 25, ["param2"] = 23, ["name"] = "cblocks:panel_stonebrick_white", ["param1"] = 14}, {["x"] = 1, ["y"] = 7, ["z"] = 26, ["param2"] = 23, ["name"] = "cblocks:panel_stonebrick_white", ["param1"] = 14}, {["x"] = 1, ["y"] = 7, ["z"] = 27, ["param2"] = 23, ["name"] = "cblocks:panel_stonebrick_white", ["param1"] = 14}, {["x"] = 1, ["y"] = 7, ["z"] = 28, ["param2"] = 23, ["name"] = "cblocks:panel_stonebrick_white", ["param1"] = 14}, {["x"] = 1, ["y"] = 7, ["z"] = 29, ["param2"] = 23, ["name"] = "cblocks:panel_stonebrick_white", ["param1"] = 14}, {["x"] = 1, ["y"] = 7, ["z"] = 30, ["param2"] = 23, ["name"] = "cblocks:micro_stonebrick_white", ["param1"] = 30}, {["x"] = 1, ["y"] = 8, ["z"] = 23, ["param2"] = 3, ["name"] = "cblocks:stair_stonebrick_white_outer", ["param1"] = 14}, {["x"] = 1, ["y"] = 8, ["z"] = 24, ["param2"] = 3, ["name"] = "cblocks:stair_stonebrick_white_outer", ["param1"] = 14}, {["x"] = 1, ["y"] = 8, ["z"] = 25, ["param2"] = 3, ["name"] = "cblocks:stair_stonebrick_white_outer", ["param1"] = 14}, {["x"] = 1, ["y"] = 8, ["z"] = 26, ["param2"] = 3, ["name"] = "cblocks:stair_stonebrick_white_outer", ["param1"] = 14}, {["x"] = 1, ["y"] = 8, ["z"] = 27, ["param2"] = 3, ["name"] = "cblocks:stair_stonebrick_white_outer", ["param1"] = 14}, {["x"] = 1, ["y"] = 8, ["z"] = 28, ["param2"] = 3, ["name"] = "cblocks:stair_stonebrick_white_outer", ["param1"] = 14}, {["x"] = 1, ["y"] = 8, ["z"] = 29, ["param2"] = 3, ["name"] = "cblocks:stair_stonebrick_white_outer", ["param1"] = 14}, {["x"] = 1, ["y"] = 8, ["z"] = 30, ["param2"] = 3, ["name"] = "cblocks:stair_stonebrick_white_outer", ["param1"] = 14}, {["x"] = 1, ["y"] = 9, ["z"] = 23, ["name"] = "cblocks:slab_stonebrick_white_2", ["param1"] = 14}, {["x"] = 1, ["y"] = 9, ["z"] = 24, ["param2"] = 3, ["name"] = "cblocks:panel_stonebrick_white_2", ["param1"] = 14}, {["x"] = 1, ["y"] = 9, ["z"] = 25, ["param2"] = 3, ["name"] = "cblocks:panel_stonebrick_white_2", ["param1"] = 14}, {["x"] = 1, ["y"] = 9, ["z"] = 26, ["param2"] = 3, ["name"] = "cblocks:panel_stonebrick_white_2", ["param1"] = 14}, {["x"] = 1, ["y"] = 9, ["z"] = 27, ["param2"] = 3, ["name"] = "cblocks:panel_stonebrick_white_2", ["param1"] = 14}, {["x"] = 1, ["y"] = 9, ["z"] = 28, ["param2"] = 3, ["name"] = "cblocks:panel_stonebrick_white_2", ["param1"] = 14}, {["x"] = 1, ["y"] = 9, ["z"] = 29, ["param2"] = 3, ["name"] = "cblocks:panel_stonebrick_white_2", ["param1"] = 14}, {["x"] = 1, ["y"] = 9, ["z"] = 30, ["name"] = "cblocks:slab_stonebrick_white_2", ["param1"] = 14}, {["x"] = 2, ["y"] = 0, ["z"] = 0, ["name"] = "default:dirt_with_grass", ["param1"] = 28}, {["x"] = 2, ["y"] = 0, ["z"] = 1, ["name"] = "default:dirt_with_grass", ["param1"] = 28}, {["x"] = 2, ["y"] = 0, ["z"] = 2, ["name"] = "default:dirt_with_grass", ["param1"] = 28}, {["x"] = 2, ["y"] = 0, ["z"] = 3, ["name"] = "default:dirt_with_grass", ["param1"] = 28}, {["x"] = 2, ["y"] = 0, ["z"] = 4, ["name"] = "default:dirt_with_grass", ["param1"] = 28}, {["x"] = 2, ["y"] = 0, ["z"] = 5, ["name"] = "default:dirt_with_grass", ["param1"] = 28}, {["x"] = 2, ["y"] = 0, ["z"] = 6, ["name"] = "default:dirt_with_grass", ["param1"] = 28}, {["x"] = 2, ["y"] = 0, ["z"] = 7, ["name"] = "default:dirt_with_grass", ["param1"] = 28}, {["x"] = 2, ["y"] = 0, ["z"] = 8, ["name"] = "default:dirt_with_grass", ["param1"] = 28}, {["x"] = 2, ["y"] = 0, ["z"] = 9, ["name"] = "default:dirt_with_grass", ["param1"] = 28}, {["x"] = 2, ["y"] = 0, ["z"] = 10, ["name"] = "default:dirt_with_grass", ["param1"] = 28}, {["x"] = 2, ["y"] = 0, ["z"] = 11, ["name"] = "default:dirt_with_grass", ["param1"] = 28}, {["x"] = 2, ["y"] = 0, ["z"] = 12, ["name"] = "default:dirt_with_grass", ["param1"] = 28}, {["x"] = 2, ["y"] = 0, ["z"] = 13, ["name"] = "default:dirt_with_grass", ["param1"] = 28}, {["x"] = 2, ["y"] = 0, ["z"] = 14, ["name"] = "default:dirt_with_grass", ["param1"] = 28}, {["x"] = 2, ["y"] = 0, ["z"] = 15, ["name"] = "default:dirt_with_grass", ["param1"] = 28}, {["x"] = 2, ["y"] = 0, ["z"] = 16, ["name"] = "default:dirt_with_grass", ["param1"] = 28}, {["x"] = 2, ["y"] = 0, ["z"] = 17, ["name"] = "default:dirt_with_grass", ["param1"] = 28}, {["x"] = 2, ["y"] = 0, ["z"] = 18, ["name"] = "default:dirt_with_grass", ["param1"] = 28}, {["x"] = 2, ["y"] = 0, ["z"] = 19, ["name"] = "default:dirt_with_grass", ["param1"] = 28}, {["x"] = 2, ["y"] = 0, ["z"] = 20, ["name"] = "default:dirt_with_grass", ["param1"] = 28}, {["x"] = 2, ["y"] = 0, ["z"] = 21, ["name"] = "default:dirt_with_grass", ["param1"] = 28}, {["x"] = 2, ["y"] = 0, ["z"] = 22, ["name"] = "default:dirt_with_grass", ["param1"] = 28}, {["x"] = 2, ["y"] = 0, ["z"] = 23, ["name"] = "default:dirt_with_grass", ["param1"] = 28}, {["x"] = 2, ["y"] = 0, ["z"] = 24, ["name"] = "default:dirt_with_grass", ["param1"] = 28}, {["x"] = 2, ["y"] = 0, ["z"] = 25, ["name"] = "default:dirt_with_grass", ["param1"] = 28}, {["x"] = 2, ["y"] = 0, ["z"] = 26, ["name"] = "default:dirt_with_grass", ["param1"] = 28}, {["x"] = 2, ["y"] = 0, ["z"] = 27, ["name"] = "default:dirt_with_grass", ["param1"] = 28}, {["x"] = 2, ["y"] = 0, ["z"] = 28, ["name"] = "default:dirt_with_grass", ["param1"] = 28}, {["x"] = 2, ["y"] = 0, ["z"] = 29, ["name"] = "default:dirt_with_grass", ["param1"] = 28}, {["x"] = 2, ["y"] = 0, ["z"] = 30, ["name"] = "default:dirt_with_grass", ["param1"] = 28}, {["x"] = 2, ["y"] = 0, ["z"] = 31, ["name"] = "default:dirt_with_grass", ["param1"] = 28}, {["x"] = 2, ["y"] = 0, ["z"] = 32, ["name"] = "default:dirt_with_grass", ["param1"] = 28}, {["x"] = 2, ["y"] = 0, ["z"] = 33, ["name"] = "default:dirt_with_grass", ["param1"] = 28}, {["x"] = 2, ["y"] = 0, ["z"] = 34, ["name"] = "default:dirt_with_grass", ["param1"] = 28}, {["x"] = 2, ["y"] = 0, ["z"] = 35, ["name"] = "default:dirt_with_grass", ["param1"] = 28}, {["x"] = 2, ["y"] = 0, ["z"] = 36, ["name"] = "default:dirt_with_grass", ["param1"] = 28}, {["x"] = 2, ["y"] = 0, ["z"] = 37, ["name"] = "default:dirt_with_grass", ["param1"] = 28}, {["x"] = 2, ["y"] = 0, ["z"] = 38, ["name"] = "default:dirt_with_grass", ["param1"] = 28}, {["x"] = 2, ["y"] = 0, ["z"] = 39, ["name"] = "default:dirt_with_grass", ["param1"] = 28}, {["x"] = 2, ["y"] = 0, ["z"] = 40, ["name"] = "default:dirt_with_grass", ["param1"] = 28}, {["x"] = 2, ["y"] = 0, ["z"] = 41, ["name"] = "default:dirt_with_grass", ["param1"] = 28}, {["x"] = 2, ["y"] = 0, ["z"] = 42, ["name"] = "default:dirt_with_grass", ["param1"] = 28}, {["x"] = 2, ["y"] = 0, ["z"] = 43, ["name"] = "default:dirt_with_grass", ["param1"] = 28}, {["x"] = 2, ["y"] = 0, ["z"] = 44, ["name"] = "default:dirt_with_grass", ["param1"] = 28}, {["x"] = 2, ["y"] = 0, ["z"] = 45, ["name"] = "default:dirt_with_grass", ["param1"] = 28}, {["x"] = 2, ["y"] = 0, ["z"] = 46, ["name"] = "default:dirt_with_grass", ["param1"] = 28}, {["x"] = 2, ["y"] = 0, ["z"] = 47, ["name"] = "default:dirt_with_grass", ["param1"] = 28}, {["x"] = 2, ["y"] = 0, ["z"] = 48, ["name"] = "default:dirt_with_grass", ["param1"] = 28}, {["x"] = 2, ["y"] = 0, ["z"] = 49, ["name"] = "default:dirt_with_grass", ["param1"] = 28}, {["x"] = 2, ["y"] = 0, ["z"] = 50, ["name"] = "default:dirt_with_grass", ["param1"] = 28}, {["x"] = 2, ["y"] = 0, ["z"] = 51, ["name"] = "default:dirt_with_grass", ["param1"] = 28}, {["x"] = 2, ["y"] = 0, ["z"] = 52, ["name"] = "default:dirt_with_grass", ["param1"] = 28}, {["x"] = 2, ["y"] = 0, ["z"] = 53, ["name"] = "default:dirt_with_grass", ["param1"] = 28}, {["x"] = 2, ["y"] = 0, ["z"] = 54, ["name"] = "default:dirt_with_grass", ["param1"] = 28}, {["x"] = 2, ["y"] = 1, ["z"] = 2, ["param2"] = 16, ["name"] = "cblocks:slab_stonebrick_brown", ["param1"] = 26}, {["x"] = 2, ["y"] = 1, ["z"] = 3, ["param2"] = 18, ["name"] = "cblocks:slab_stonebrick_brown", ["param1"] = 43}, {["x"] = 2, ["y"] = 1, ["z"] = 4, ["param2"] = 18, ["name"] = "cblocks:slab_stonebrick_brown", ["param1"] = 60}, {["x"] = 2, ["y"] = 1, ["z"] = 5, ["param2"] = 18, ["name"] = "cblocks:slab_stonebrick_brown", ["param1"] = 61}, {["x"] = 2, ["y"] = 1, ["z"] = 6, ["param2"] = 18, ["name"] = "cblocks:slab_stonebrick_brown", ["param1"] = 46}, {["x"] = 2, ["y"] = 1, ["z"] = 7, ["param2"] = 16, ["name"] = "cblocks:slab_stonebrick_brown", ["param1"] = 62}, {["x"] = 2, ["y"] = 1, ["z"] = 8, ["param2"] = 16, ["name"] = "cblocks:slab_stonebrick_brown", ["param1"] = 62}, {["x"] = 2, ["y"] = 1, ["z"] = 9, ["param2"] = 16, ["name"] = "cblocks:slab_stonebrick_brown", ["param1"] = 46}, {["x"] = 2, ["y"] = 1, ["z"] = 12, ["param2"] = 18, ["name"] = "cblocks:slab_stonebrick_brown", ["param1"] = 46}, {["x"] = 2, ["y"] = 1, ["z"] = 13, ["param2"] = 16, ["name"] = "cblocks:slab_stonebrick_brown", ["param1"] = 62}, {["x"] = 2, ["y"] = 1, ["z"] = 14, ["param2"] = 16, ["name"] = "cblocks:slab_stonebrick_brown", ["param1"] = 62}, {["x"] = 2, ["y"] = 1, ["z"] = 15, ["param2"] = 16, ["name"] = "cblocks:slab_stonebrick_brown", ["param1"] = 46}, {["x"] = 2, ["y"] = 1, ["z"] = 16, ["param2"] = 18, ["name"] = "cblocks:slab_stonebrick_brown", ["param1"] = 30}, {["x"] = 2, ["y"] = 1, ["z"] = 17, ["param2"] = 18, ["name"] = "cblocks:slab_stonebrick_brown", ["param1"] = 46}, {["x"] = 2, ["y"] = 1, ["z"] = 18, ["param2"] = 18, ["name"] = "cblocks:slab_stonebrick_brown", ["param1"] = 62}, {["x"] = 2, ["y"] = 1, ["z"] = 19, ["param2"] = 16, ["name"] = "cblocks:slab_stonebrick_brown", ["param1"] = 62}, {["x"] = 2, ["y"] = 1, ["z"] = 20, ["param2"] = 16, ["name"] = "cblocks:slab_stonebrick_brown", ["param1"] = 46}, {["x"] = 2, ["y"] = 1, ["z"] = 21, ["param2"] = 16, ["name"] = "cblocks:slab_stonebrick_brown", ["param1"] = 61}, {["x"] = 2, ["y"] = 1, ["z"] = 22, ["param2"] = 18, ["name"] = "cblocks:slab_stonebrick_brown", ["param1"] = 60}, {["x"] = 2, ["y"] = 1, ["z"] = 23, ["param2"] = 18, ["name"] = "cblocks:slab_stonebrick_brown", ["param1"] = 45}, {["x"] = 2, ["y"] = 1, ["z"] = 24, ["param2"] = 1, ["name"] = "facade:clay_bannerstone_corner", ["param1"] = 29}, {["x"] = 2, ["y"] = 1, ["z"] = 29, ["param2"] = 1, ["name"] = "facade:clay_bannerstone_corner", ["param1"] = 29}, {["x"] = 2, ["y"] = 1, ["z"] = 30, ["param2"] = 18, ["name"] = "cblocks:slab_stonebrick_brown", ["param1"] = 45}, {["x"] = 2, ["y"] = 1, ["z"] = 31, ["param2"] = 18, ["name"] = "cblocks:slab_stonebrick_brown", ["param1"] = 60}, {["x"] = 2, ["y"] = 1, ["z"] = 32, ["param2"] = 16, ["name"] = "cblocks:slab_stonebrick_brown", ["param1"] = 61}, {["x"] = 2, ["y"] = 1, ["z"] = 33, ["param2"] = 16, ["name"] = "cblocks:slab_stonebrick_brown", ["param1"] = 46}, {["x"] = 2, ["y"] = 1, ["z"] = 34, ["param2"] = 16, ["name"] = "cblocks:slab_stonebrick_brown", ["param1"] = 62}, {["x"] = 2, ["y"] = 1, ["z"] = 35, ["param2"] = 18, ["name"] = "cblocks:slab_stonebrick_brown", ["param1"] = 62}, {["x"] = 2, ["y"] = 1, ["z"] = 36, ["param2"] = 18, ["name"] = "cblocks:slab_stonebrick_brown", ["param1"] = 46}, {["x"] = 2, ["y"] = 1, ["z"] = 37, ["param2"] = 18, ["name"] = "cblocks:slab_stonebrick_brown", ["param1"] = 30}, {["x"] = 2, ["y"] = 1, ["z"] = 38, ["param2"] = 16, ["name"] = "cblocks:slab_stonebrick_brown", ["param1"] = 46}, {["x"] = 2, ["y"] = 1, ["z"] = 39, ["param2"] = 16, ["name"] = "cblocks:slab_stonebrick_brown", ["param1"] = 62}, {["x"] = 2, ["y"] = 1, ["z"] = 40, ["param2"] = 16, ["name"] = "cblocks:slab_stonebrick_brown", ["param1"] = 62}, {["x"] = 2, ["y"] = 1, ["z"] = 41, ["param2"] = 18, ["name"] = "cblocks:slab_stonebrick_brown", ["param1"] = 46}, {["x"] = 2, ["y"] = 1, ["z"] = 44, ["param2"] = 16, ["name"] = "cblocks:slab_stonebrick_brown", ["param1"] = 46}, {["x"] = 2, ["y"] = 1, ["z"] = 45, ["param2"] = 16, ["name"] = "cblocks:slab_stonebrick_brown", ["param1"] = 62}, {["x"] = 2, ["y"] = 1, ["z"] = 46, ["param2"] = 16, ["name"] = "cblocks:slab_stonebrick_brown", ["param1"] = 62}, {["x"] = 2, ["y"] = 1, ["z"] = 47, ["param2"] = 18, ["name"] = "cblocks:slab_stonebrick_brown", ["param1"] = 46}, {["x"] = 2, ["y"] = 1, ["z"] = 48, ["param2"] = 18, ["name"] = "cblocks:slab_stonebrick_brown", ["param1"] = 62}, {["x"] = 2, ["y"] = 1, ["z"] = 49, ["param2"] = 18, ["name"] = "cblocks:slab_stonebrick_brown", ["param1"] = 62}, {["x"] = 2, ["y"] = 1, ["z"] = 50, ["param2"] = 18, ["name"] = "cblocks:slab_stonebrick_brown", ["param1"] = 46}, {["x"] = 2, ["y"] = 1, ["z"] = 51, ["param2"] = 16, ["name"] = "cblocks:slab_stonebrick_brown", ["param1"] = 30}, {["x"] = 2, ["y"] = 2, ["z"] = 2, ["param2"] = 16, ["name"] = "cblocks:slab_stonebrick_brown", ["param1"] = 42}, {["x"] = 2, ["y"] = 2, ["z"] = 3, ["param2"] = 5, ["name"] = "cblocks:micro_stonebrick_brown", ["param1"] = 59}, {["x"] = 2, ["y"] = 2, ["z"] = 9, ["param2"] = 16, ["name"] = "cblocks:panel_stonebrick_brown_4", ["param1"] = 62}, {["x"] = 2, ["y"] = 2, ["z"] = 12, ["param2"] = 18, ["name"] = "cblocks:panel_stonebrick_brown_4", ["param1"] = 62}, {["x"] = 2, ["y"] = 2, ["z"] = 16, ["param2"] = 16, ["name"] = "cblocks:slab_stonebrick_brown", ["param1"] = 46}, {["x"] = 2, ["y"] = 2, ["z"] = 17, ["param2"] = 2, ["name"] = "cblocks:micro_stonebrick_brown", ["param1"] = 62}, {["x"] = 2, ["y"] = 2, ["z"] = 24, ["param2"] = 1, ["name"] = "facade:clay_column_corner", ["param1"] = 45}, {["x"] = 2, ["y"] = 2, ["z"] = 29, ["param2"] = 1, ["name"] = "facade:clay_column_corner", ["param1"] = 45}, {["x"] = 2, ["y"] = 2, ["z"] = 36, ["param2"] = 16, ["name"] = "cblocks:micro_stonebrick_brown", ["param1"] = 62}, {["x"] = 2, ["y"] = 2, ["z"] = 37, ["param2"] = 16, ["name"] = "cblocks:slab_stonebrick_brown", ["param1"] = 46}, {["x"] = 2, ["y"] = 2, ["z"] = 41, ["param2"] = 16, ["name"] = "cblocks:panel_stonebrick_brown_4", ["param1"] = 62}, {["x"] = 2, ["y"] = 2, ["z"] = 44, ["param2"] = 18, ["name"] = "cblocks:panel_stonebrick_brown_4", ["param1"] = 62}, {["x"] = 2, ["y"] = 2, ["z"] = 50, ["param2"] = 1, ["name"] = "cblocks:micro_stonebrick_brown", ["param1"] = 62}, {["x"] = 2, ["y"] = 2, ["z"] = 51, ["param2"] = 16, ["name"] = "cblocks:slab_stonebrick_brown", ["param1"] = 46}, {["x"] = 2, ["y"] = 3, ["z"] = 2, ["param2"] = 16, ["name"] = "cblocks:slab_stonebrick_brown", ["param1"] = 42}, {["x"] = 2, ["y"] = 3, ["z"] = 3, ["param2"] = 5, ["name"] = "cblocks:micro_stonebrick_brown", ["param1"] = 59}, {["x"] = 2, ["y"] = 3, ["z"] = 9, ["param2"] = 16, ["name"] = "cblocks:panel_stonebrick_brown_4", ["param1"] = 62}, {["x"] = 2, ["y"] = 3, ["z"] = 10, ["param2"] = 23, ["name"] = "cblocks:panel_stonebrick_brown_4", ["param1"] = 46}, {["x"] = 2, ["y"] = 3, ["z"] = 11, ["param2"] = 23, ["name"] = "cblocks:panel_stonebrick_brown_4", ["param1"] = 46}, {["x"] = 2, ["y"] = 3, ["z"] = 12, ["param2"] = 18, ["name"] = "cblocks:panel_stonebrick_brown_4", ["param1"] = 62}, {["x"] = 2, ["y"] = 3, ["z"] = 16, ["param2"] = 16, ["name"] = "cblocks:slab_stonebrick_brown", ["param1"] = 46}, {["x"] = 2, ["y"] = 3, ["z"] = 17, ["param2"] = 5, ["name"] = "cblocks:micro_stonebrick_brown", ["param1"] = 62}, {["x"] = 2, ["y"] = 3, ["z"] = 24, ["param2"] = 1, ["name"] = "facade:clay_column_corner", ["param1"] = 45}, {["x"] = 2, ["y"] = 3, ["z"] = 29, ["param2"] = 1, ["name"] = "facade:clay_column_corner", ["param1"] = 45}, {["x"] = 2, ["y"] = 3, ["z"] = 36, ["param2"] = 16, ["name"] = "cblocks:micro_stonebrick_brown", ["param1"] = 62}, {["x"] = 2, ["y"] = 3, ["z"] = 37, ["param2"] = 16, ["name"] = "cblocks:slab_stonebrick_brown", ["param1"] = 46}, {["x"] = 2, ["y"] = 3, ["z"] = 41, ["param2"] = 16, ["name"] = "cblocks:panel_stonebrick_brown_4", ["param1"] = 62}, {["x"] = 2, ["y"] = 3, ["z"] = 42, ["param2"] = 23, ["name"] = "cblocks:panel_stonebrick_brown_4", ["param1"] = 46}, {["x"] = 2, ["y"] = 3, ["z"] = 43, ["param2"] = 23, ["name"] = "cblocks:panel_stonebrick_brown_4", ["param1"] = 46}, {["x"] = 2, ["y"] = 3, ["z"] = 44, ["param2"] = 18, ["name"] = "cblocks:panel_stonebrick_brown_4", ["param1"] = 62}, {["x"] = 2, ["y"] = 3, ["z"] = 50, ["param2"] = 16, ["name"] = "cblocks:micro_stonebrick_brown", ["param1"] = 62}, {["x"] = 2, ["y"] = 3, ["z"] = 51, ["param2"] = 16, ["name"] = "cblocks:slab_stonebrick_brown", ["param1"] = 46}, {["x"] = 2, ["y"] = 4, ["z"] = 2, ["param2"] = 16, ["name"] = "cblocks:slab_stonebrick_brown", ["param1"] = 26}, {["x"] = 2, ["y"] = 4, ["z"] = 3, ["param2"] = 5, ["name"] = "cblocks:micro_stonebrick_brown", ["param1"] = 43}, {["x"] = 2, ["y"] = 4, ["z"] = 10, ["name"] = "cblocks:slope_stonebrick_brown", ["param1"] = 30}, {["x"] = 2, ["y"] = 4, ["z"] = 11, ["param2"] = 2, ["name"] = "cblocks:slope_stonebrick_brown", ["param1"] = 30}, {["x"] = 2, ["y"] = 4, ["z"] = 16, ["param2"] = 16, ["name"] = "cblocks:slab_stonebrick_brown", ["param1"] = 46}, {["x"] = 2, ["y"] = 4, ["z"] = 17, ["param2"] = 5, ["name"] = "cblocks:micro_stonebrick_brown", ["param1"] = 62}, {["x"] = 2, ["y"] = 4, ["z"] = 24, ["param2"] = 1, ["name"] = "facade:clay_column_corner", ["param1"] = 45}, {["x"] = 2, ["y"] = 4, ["z"] = 29, ["param2"] = 1, ["name"] = "facade:clay_column_corner", ["param1"] = 45}, {["x"] = 2, ["y"] = 4, ["z"] = 36, ["param2"] = 16, ["name"] = "cblocks:micro_stonebrick_brown", ["param1"] = 62}, {["x"] = 2, ["y"] = 4, ["z"] = 37, ["param2"] = 16, ["name"] = "cblocks:slab_stonebrick_brown", ["param1"] = 46}, {["x"] = 2, ["y"] = 4, ["z"] = 42, ["name"] = "cblocks:slope_stonebrick_brown", ["param1"] = 30}, {["x"] = 2, ["y"] = 4, ["z"] = 43, ["param2"] = 2, ["name"] = "cblocks:slope_stonebrick_brown", ["param1"] = 30}, {["x"] = 2, ["y"] = 4, ["z"] = 50, ["param2"] = 16, ["name"] = "cblocks:micro_stonebrick_brown", ["param1"] = 46}, {["x"] = 2, ["y"] = 4, ["z"] = 51, ["param2"] = 16, ["name"] = "cblocks:slab_stonebrick_brown", ["param1"] = 30}, {["x"] = 2, ["y"] = 5, ["z"] = 2, ["param2"] = 16, ["name"] = "cblocks:slab_stonebrick_brown", ["param1"] = 10}, {["x"] = 2, ["y"] = 5, ["z"] = 3, ["param2"] = 5, ["name"] = "cblocks:micro_stonebrick_brown", ["param1"] = 27}, {["x"] = 2, ["y"] = 5, ["z"] = 16, ["param2"] = 16, ["name"] = "cblocks:slab_stonebrick_brown", ["param1"] = 46}, {["x"] = 2, ["y"] = 5, ["z"] = 17, ["param2"] = 5, ["name"] = "cblocks:micro_stonebrick_brown", ["param1"] = 62}, {["x"] = 2, ["y"] = 5, ["z"] = 24, ["param2"] = 1, ["name"] = "facade:clay_column_corner", ["param1"] = 45}, {["x"] = 2, ["y"] = 5, ["z"] = 29, ["param2"] = 1, ["name"] = "facade:clay_column_corner", ["param1"] = 45}, {["x"] = 2, ["y"] = 5, ["z"] = 36, ["param2"] = 16, ["name"] = "cblocks:micro_stonebrick_brown", ["param1"] = 62}, {["x"] = 2, ["y"] = 5, ["z"] = 37, ["param2"] = 16, ["name"] = "cblocks:slab_stonebrick_brown", ["param1"] = 46}, {["x"] = 2, ["y"] = 5, ["z"] = 50, ["param2"] = 16, ["name"] = "cblocks:micro_stonebrick_brown", ["param1"] = 30}, {["x"] = 2, ["y"] = 5, ["z"] = 51, ["param2"] = 16, ["name"] = "cblocks:slab_stonebrick_brown", ["param1"] = 14}, {["x"] = 2, ["y"] = 6, ["z"] = 2, ["param2"] = 16, ["name"] = "cblocks:slab_stonebrick_brown", ["param1"] = 10}, {["x"] = 2, ["y"] = 6, ["z"] = 3, ["param2"] = 5, ["name"] = "cblocks:micro_stonebrick_brown", ["param1"] = 11}, {["x"] = 2, ["y"] = 6, ["z"] = 16, ["param2"] = 16, ["name"] = "cblocks:slab_stonebrick_brown", ["param1"] = 46}, {["x"] = 2, ["y"] = 6, ["z"] = 17, ["param2"] = 2, ["name"] = "cblocks:micro_stonebrick_brown", ["param1"] = 62}, {["x"] = 2, ["y"] = 6, ["z"] = 24, ["param2"] = 1, ["name"] = "facade:clay_bannerstone_corner", ["param1"] = 45}, {["x"] = 2, ["y"] = 6, ["z"] = 25, ["param2"] = 23, ["name"] = "cblocks:slab_stonebrick_white_quarter", ["param1"] = 29}, {["x"] = 2, ["y"] = 6, ["z"] = 26, ["param2"] = 23, ["name"] = "cblocks:slab_stonebrick_white_quarter", ["param1"] = 13}, {["x"] = 2, ["y"] = 6, ["z"] = 27, ["param2"] = 23, ["name"] = "cblocks:slab_stonebrick_white_quarter", ["param1"] = 13}, {["x"] = 2, ["y"] = 6, ["z"] = 28, ["param2"] = 23, ["name"] = "cblocks:slab_stonebrick_white_quarter", ["param1"] = 29}, {["x"] = 2, ["y"] = 6, ["z"] = 29, ["param2"] = 1, ["name"] = "facade:clay_bannerstone_corner", ["param1"] = 45}, {["x"] = 2, ["y"] = 6, ["z"] = 36, ["param2"] = 16, ["name"] = "cblocks:micro_stonebrick_brown", ["param1"] = 62}, {["x"] = 2, ["y"] = 6, ["z"] = 37, ["param2"] = 16, ["name"] = "cblocks:slab_stonebrick_brown", ["param1"] = 46}, {["x"] = 2, ["y"] = 6, ["z"] = 50, ["param2"] = 16, ["name"] = "cblocks:micro_stonebrick_brown", ["param1"] = 14}, {["x"] = 2, ["y"] = 6, ["z"] = 51, ["param2"] = 16, ["name"] = "cblocks:slab_stonebrick_brown", ["param1"] = 14}, {["x"] = 2, ["y"] = 7, ["z"] = 2, ["param2"] = 16, ["name"] = "cblocks:slab_stonebrick_brown", ["param1"] = 10}, {["x"] = 2, ["y"] = 7, ["z"] = 3, ["param2"] = 5, ["name"] = "cblocks:micro_stonebrick_brown", ["param1"] = 11}, {["x"] = 2, ["y"] = 7, ["z"] = 4, ["param2"] = 1, ["name"] = "cblocks:panel_stonebrick_brown", ["param1"] = 12}, {["x"] = 2, ["y"] = 7, ["z"] = 5, ["param2"] = 1, ["name"] = "cblocks:panel_stonebrick_brown", ["param1"] = 13}, {["x"] = 2, ["y"] = 7, ["z"] = 7, ["param2"] = 1, ["name"] = "cblocks:panel_stonebrick_brown", ["param1"] = 14}, {["x"] = 2, ["y"] = 7, ["z"] = 8, ["param2"] = 1, ["name"] = "cblocks:panel_stonebrick_brown", ["param1"] = 14}, {["x"] = 2, ["y"] = 7, ["z"] = 10, ["param2"] = 1, ["name"] = "cblocks:panel_stonebrick_brown", ["param1"] = 14}, {["x"] = 2, ["y"] = 7, ["z"] = 11, ["param2"] = 1, ["name"] = "cblocks:panel_stonebrick_brown", ["param1"] = 14}, {["x"] = 2, ["y"] = 7, ["z"] = 13, ["param2"] = 1, ["name"] = "cblocks:panel_stonebrick_brown", ["param1"] = 14}, {["x"] = 2, ["y"] = 7, ["z"] = 14, ["param2"] = 1, ["name"] = "cblocks:panel_stonebrick_brown", ["param1"] = 14}, {["x"] = 2, ["y"] = 7, ["z"] = 16, ["param2"] = 16, ["name"] = "cblocks:slab_stonebrick_brown", ["param1"] = 30}, {["x"] = 2, ["y"] = 7, ["z"] = 17, ["param2"] = 22, ["name"] = "cblocks:stair_stonebrick_brown_right_half", ["param1"] = 46}, {["x"] = 2, ["y"] = 7, ["z"] = 18, ["param2"] = 23, ["name"] = "cblocks:panel_stonebrick_brown", ["param1"] = 62}, {["x"] = 2, ["y"] = 7, ["z"] = 19, ["param2"] = 23, ["name"] = "cblocks:panel_stonebrick_brown", ["param1"] = 62}, {["x"] = 2, ["y"] = 7, ["z"] = 20, ["param2"] = 23, ["name"] = "cblocks:panel_stonebrick_brown", ["param1"] = 46}, {["x"] = 2, ["y"] = 7, ["z"] = 21, ["param2"] = 23, ["name"] = "cblocks:panel_stonebrick_brown", ["param1"] = 62}, {["x"] = 2, ["y"] = 7, ["z"] = 22, ["param2"] = 23, ["name"] = "cblocks:panel_stonebrick_brown", ["param1"] = 62}, {["x"] = 2, ["y"] = 7, ["z"] = 23, ["param2"] = 9, ["name"] = "cblocks:stair_stonebrick_brown_half", ["param1"] = 45}, {["x"] = 2, ["y"] = 7, ["z"] = 24, ["param2"] = 2, ["name"] = "angledwalls:angled_walldesert_sandstone_brick", ["param1"] = 29}, {["x"] = 2, ["y"] = 7, ["z"] = 25, ["param2"] = 1, ["name"] = "angledwalls:angled_walldesert_sandstone_brick", ["param1"] = 13}, {["x"] = 2, ["y"] = 7, ["z"] = 26, ["param2"] = 2, ["name"] = "angledwalls:angled_walldesert_sandstone_brick", ["param1"] = 13}, {["x"] = 2, ["y"] = 7, ["z"] = 27, ["param2"] = 2, ["name"] = "angledwalls:angled_walldesert_sandstone_brick", ["param1"] = 13}, {["x"] = 2, ["y"] = 7, ["z"] = 28, ["param2"] = 1, ["name"] = "angledwalls:angled_walldesert_sandstone_brick", ["param1"] = 13}, {["x"] = 2, ["y"] = 7, ["z"] = 29, ["param2"] = 2, ["name"] = "angledwalls:angled_walldesert_sandstone_brick", ["param1"] = 29}, {["x"] = 2, ["y"] = 7, ["z"] = 30, ["param2"] = 9, ["name"] = "cblocks:stair_stonebrick_brown_half", ["param1"] = 45}, {["x"] = 2, ["y"] = 7, ["z"] = 31, ["param2"] = 23, ["name"] = "cblocks:panel_stonebrick_brown", ["param1"] = 62}, {["x"] = 2, ["y"] = 7, ["z"] = 32, ["param2"] = 23, ["name"] = "cblocks:panel_stonebrick_brown", ["param1"] = 62}, {["x"] = 2, ["y"] = 7, ["z"] = 33, ["param2"] = 23, ["name"] = "cblocks:panel_stonebrick_brown", ["param1"] = 46}, {["x"] = 2, ["y"] = 7, ["z"] = 34, ["param2"] = 23, ["name"] = "cblocks:panel_stonebrick_brown", ["param1"] = 62}, {["x"] = 2, ["y"] = 7, ["z"] = 35, ["param2"] = 23, ["name"] = "cblocks:panel_stonebrick_brown", ["param1"] = 62}, {["x"] = 2, ["y"] = 7, ["z"] = 36, ["param2"] = 20, ["name"] = "cblocks:stair_stonebrick_brown_half", ["param1"] = 46}, {["x"] = 2, ["y"] = 7, ["z"] = 37, ["param2"] = 16, ["name"] = "cblocks:slab_stonebrick_brown", ["param1"] = 30}, {["x"] = 2, ["y"] = 7, ["z"] = 39, ["param2"] = 1, ["name"] = "cblocks:panel_stonebrick_brown", ["param1"] = 14}, {["x"] = 2, ["y"] = 7, ["z"] = 40, ["param2"] = 1, ["name"] = "cblocks:panel_stonebrick_brown", ["param1"] = 14}, {["x"] = 2, ["y"] = 7, ["z"] = 42, ["param2"] = 1, ["name"] = "cblocks:panel_stonebrick_brown", ["param1"] = 14}, {["x"] = 2, ["y"] = 7, ["z"] = 43, ["param2"] = 1, ["name"] = "cblocks:panel_stonebrick_brown", ["param1"] = 14}, {["x"] = 2, ["y"] = 7, ["z"] = 45, ["param2"] = 1, ["name"] = "cblocks:panel_stonebrick_brown", ["param1"] = 14}, {["x"] = 2, ["y"] = 7, ["z"] = 46, ["param2"] = 1, ["name"] = "cblocks:panel_stonebrick_brown", ["param1"] = 14}, {["x"] = 2, ["y"] = 7, ["z"] = 48, ["param2"] = 1, ["name"] = "cblocks:panel_stonebrick_brown", ["param1"] = 14}, {["x"] = 2, ["y"] = 7, ["z"] = 49, ["param2"] = 1, ["name"] = "cblocks:panel_stonebrick_brown", ["param1"] = 14}, {["x"] = 2, ["y"] = 7, ["z"] = 50, ["param2"] = 16, ["name"] = "cblocks:micro_stonebrick_brown", ["param1"] = 14}, {["x"] = 2, ["y"] = 7, ["z"] = 51, ["param2"] = 16, ["name"] = "cblocks:slab_stonebrick_brown", ["param1"] = 14}, {["x"] = 2, ["y"] = 8, ["z"] = 2, ["param2"] = 16, ["name"] = "cblocks:slab_stonebrick_brown", ["param1"] = 10}, {["x"] = 2, ["y"] = 8, ["z"] = 3, ["param2"] = 5, ["name"] = "cblocks:micro_stonebrick_brown", ["param1"] = 11}, {["x"] = 2, ["y"] = 8, ["z"] = 16, ["param2"] = 16, ["name"] = "cblocks:slab_stonebrick_brown", ["param1"] = 14}, {["x"] = 2, ["y"] = 8, ["z"] = 17, ["param2"] = 5, ["name"] = "cblocks:micro_stonebrick_brown", ["param1"] = 30}, {["x"] = 2, ["y"] = 8, ["z"] = 18, ["param2"] = 16, ["name"] = "cblocks:slab_stonebrick_brown", ["param1"] = 46}, {["x"] = 2, ["y"] = 8, ["z"] = 19, ["param2"] = 18, ["name"] = "cblocks:slab_stonebrick_brown", ["param1"] = 46}, {["x"] = 2, ["y"] = 8, ["z"] = 21, ["param2"] = 16, ["name"] = "cblocks:slab_stonebrick_brown", ["param1"] = 46}, {["x"] = 2, ["y"] = 8, ["z"] = 22, ["param2"] = 18, ["name"] = "cblocks:slab_stonebrick_brown", ["param1"] = 46}, {["x"] = 2, ["y"] = 8, ["z"] = 23, ["param2"] = 1, ["name"] = "cblocks:slab_stonebrick_white", ["param1"] = 29}, {["x"] = 2, ["y"] = 8, ["z"] = 24, ["param2"] = 1, ["name"] = "cblocks:slab_stonebrick_white", ["param1"] = 13}, {["x"] = 2, ["y"] = 8, ["z"] = 25, ["param2"] = 1, ["name"] = "cblocks:slab_stonebrick_white", ["param1"] = 13}, {["x"] = 2, ["y"] = 8, ["z"] = 26, ["param2"] = 1, ["name"] = "cblocks:slab_stonebrick_white", ["param1"] = 13}, {["x"] = 2, ["y"] = 8, ["z"] = 27, ["param2"] = 1, ["name"] = "cblocks:slab_stonebrick_white", ["param1"] = 13}, {["x"] = 2, ["y"] = 8, ["z"] = 28, ["param2"] = 1, ["name"] = "cblocks:slab_stonebrick_white", ["param1"] = 13}, {["x"] = 2, ["y"] = 8, ["z"] = 29, ["param2"] = 1, ["name"] = "cblocks:slab_stonebrick_white", ["param1"] = 13}, {["x"] = 2, ["y"] = 8, ["z"] = 30, ["param2"] = 1, ["name"] = "cblocks:slab_stonebrick_white", ["param1"] = 29}, {["x"] = 2, ["y"] = 8, ["z"] = 31, ["param2"] = 18, ["name"] = "cblocks:slab_stonebrick_brown", ["param1"] = 46}, {["x"] = 2, ["y"] = 8, ["z"] = 32, ["param2"] = 16, ["name"] = "cblocks:slab_stonebrick_brown", ["param1"] = 46}, {["x"] = 2, ["y"] = 8, ["z"] = 34, ["param2"] = 18, ["name"] = "cblocks:slab_stonebrick_brown", ["param1"] = 46}, {["x"] = 2, ["y"] = 8, ["z"] = 35, ["param2"] = 16, ["name"] = "cblocks:slab_stonebrick_brown", ["param1"] = 46}, {["x"] = 2, ["y"] = 8, ["z"] = 36, ["param2"] = 16, ["name"] = "cblocks:micro_stonebrick_brown", ["param1"] = 30}, {["x"] = 2, ["y"] = 8, ["z"] = 37, ["param2"] = 16, ["name"] = "cblocks:slab_stonebrick_brown", ["param1"] = 14}, {["x"] = 2, ["y"] = 8, ["z"] = 50, ["param2"] = 16, ["name"] = "cblocks:micro_stonebrick_brown", ["param1"] = 14}, {["x"] = 2, ["y"] = 8, ["z"] = 51, ["param2"] = 16, ["name"] = "cblocks:slab_stonebrick_brown", ["param1"] = 14}, {["x"] = 2, ["y"] = 9, ["z"] = 2, ["param2"] = 16, ["name"] = "cblocks:slab_stonebrick_brown", ["param1"] = 10}, {["x"] = 2, ["y"] = 9, ["z"] = 3, ["param2"] = 5, ["name"] = "cblocks:micro_stonebrick_brown", ["param1"] = 11}, {["x"] = 2, ["y"] = 9, ["z"] = 16, ["param2"] = 16, ["name"] = "cblocks:slab_stonebrick_brown", ["param1"] = 14}, {["x"] = 2, ["y"] = 9, ["z"] = 17, ["param2"] = 5, ["name"] = "cblocks:micro_stonebrick_brown", ["param1"] = 14}, {["x"] = 2, ["y"] = 9, ["z"] = 23, ["param2"] = 2, ["name"] = "cblocks:panel_stonebrick_white_2", ["param1"] = 13}, {["x"] = 2, ["y"] = 9, ["z"] = 30, ["name"] = "cblocks:panel_stonebrick_white_2", ["param1"] = 13}, {["x"] = 2, ["y"] = 9, ["z"] = 36, ["param2"] = 16, ["name"] = "cblocks:micro_stonebrick_brown", ["param1"] = 14}, {["x"] = 2, ["y"] = 9, ["z"] = 37, ["param2"] = 16, ["name"] = "cblocks:slab_stonebrick_brown", ["param1"] = 14}, {["x"] = 2, ["y"] = 9, ["z"] = 50, ["param2"] = 16, ["name"] = "cblocks:micro_stonebrick_brown", ["param1"] = 14}, {["x"] = 2, ["y"] = 9, ["z"] = 51, ["param2"] = 16, ["name"] = "cblocks:slab_stonebrick_brown", ["param1"] = 14}, {["x"] = 2, ["y"] = 10, ["z"] = 2, ["param2"] = 16, ["name"] = "cblocks:slab_stonebrick_brown", ["param1"] = 10}, {["x"] = 2, ["y"] = 10, ["z"] = 3, ["param2"] = 5, ["name"] = "cblocks:micro_stonebrick_brown", ["param1"] = 11}, {["x"] = 2, ["y"] = 10, ["z"] = 16, ["param2"] = 16, ["name"] = "cblocks:slab_stonebrick_brown", ["param1"] = 14}, {["x"] = 2, ["y"] = 10, ["z"] = 17, ["param2"] = 2, ["name"] = "cblocks:micro_stonebrick_brown", ["param1"] = 14}, {["x"] = 2, ["y"] = 10, ["z"] = 36, ["param2"] = 16, ["name"] = "cblocks:micro_stonebrick_brown", ["param1"] = 14}, {["x"] = 2, ["y"] = 10, ["z"] = 37, ["param2"] = 16, ["name"] = "cblocks:slab_stonebrick_brown", ["param1"] = 14}, {["x"] = 2, ["y"] = 10, ["z"] = 50, ["param2"] = 16, ["name"] = "cblocks:micro_stonebrick_brown", ["param1"] = 14}, {["x"] = 2, ["y"] = 10, ["z"] = 51, ["param2"] = 16, ["name"] = "cblocks:slab_stonebrick_brown", ["param1"] = 14}, {["x"] = 2, ["y"] = 11, ["z"] = 2, ["param2"] = 16, ["name"] = "cblocks:slab_stonebrick_brown", ["param1"] = 10}, {["x"] = 2, ["y"] = 11, ["z"] = 3, ["param2"] = 5, ["name"] = "cblocks:micro_stonebrick_brown", ["param1"] = 11}, {["x"] = 2, ["y"] = 11, ["z"] = 16, ["param2"] = 16, ["name"] = "cblocks:slab_stonebrick_brown", ["param1"] = 14}, {["x"] = 2, ["y"] = 11, ["z"] = 17, ["param2"] = 5, ["name"] = "cblocks:micro_stonebrick_brown", ["param1"] = 14}, {["x"] = 2, ["y"] = 11, ["z"] = 36, ["param2"] = 16, ["name"] = "cblocks:micro_stonebrick_brown", ["param1"] = 14}, {["x"] = 2, ["y"] = 11, ["z"] = 37, ["param2"] = 16, ["name"] = "cblocks:slab_stonebrick_brown", ["param1"] = 14}, {["x"] = 2, ["y"] = 11, ["z"] = 50, ["param2"] = 16, ["name"] = "cblocks:micro_stonebrick_brown", ["param1"] = 14}, {["x"] = 2, ["y"] = 11, ["z"] = 51, ["param2"] = 16, ["name"] = "cblocks:slab_stonebrick_brown", ["param1"] = 14}, {["x"] = 2, ["y"] = 12, ["z"] = 2, ["param2"] = 16, ["name"] = "cblocks:slab_stonebrick_brown", ["param1"] = 10}, {["x"] = 2, ["y"] = 12, ["z"] = 3, ["param2"] = 5, ["name"] = "cblocks:micro_stonebrick_brown", ["param1"] = 11}, {["x"] = 2, ["y"] = 12, ["z"] = 16, ["param2"] = 16, ["name"] = "cblocks:slab_stonebrick_brown", ["param1"] = 14}, {["x"] = 2, ["y"] = 12, ["z"] = 17, ["param2"] = 5, ["name"] = "cblocks:micro_stonebrick_brown", ["param1"] = 14}, {["x"] = 2, ["y"] = 12, ["z"] = 18, ["param2"] = 23, ["name"] = "cblocks:panel_stonebrick_brown_2", ["param1"] = 14}, {["x"] = 2, ["y"] = 12, ["z"] = 19, ["param2"] = 23, ["name"] = "cblocks:panel_stonebrick_brown_2", ["param1"] = 14}, {["x"] = 2, ["y"] = 12, ["z"] = 21, ["param2"] = 23, ["name"] = "cblocks:panel_stonebrick_brown_2", ["param1"] = 14}, {["x"] = 2, ["y"] = 12, ["z"] = 22, ["param2"] = 23, ["name"] = "cblocks:panel_stonebrick_brown_2", ["param1"] = 14}, {["x"] = 2, ["y"] = 12, ["z"] = 24, ["param2"] = 23, ["name"] = "cblocks:panel_stonebrick_brown_2", ["param1"] = 14}, {["x"] = 2, ["y"] = 12, ["z"] = 25, ["param2"] = 23, ["name"] = "cblocks:panel_stonebrick_brown_2", ["param1"] = 14}, {["x"] = 2, ["y"] = 12, ["z"] = 28, ["param2"] = 23, ["name"] = "cblocks:panel_stonebrick_brown_2", ["param1"] = 14}, {["x"] = 2, ["y"] = 12, ["z"] = 29, ["param2"] = 23, ["name"] = "cblocks:panel_stonebrick_brown_2", ["param1"] = 14}, {["x"] = 2, ["y"] = 12, ["z"] = 31, ["param2"] = 23, ["name"] = "cblocks:panel_stonebrick_brown_2", ["param1"] = 14}, {["x"] = 2, ["y"] = 12, ["z"] = 32, ["param2"] = 23, ["name"] = "cblocks:panel_stonebrick_brown_2", ["param1"] = 14}, {["x"] = 2, ["y"] = 12, ["z"] = 34, ["param2"] = 23, ["name"] = "cblocks:panel_stonebrick_brown_2", ["param1"] = 14}, {["x"] = 2, ["y"] = 12, ["z"] = 35, ["param2"] = 23, ["name"] = "cblocks:panel_stonebrick_brown_2", ["param1"] = 14}, {["x"] = 2, ["y"] = 12, ["z"] = 36, ["param2"] = 16, ["name"] = "cblocks:micro_stonebrick_brown", ["param1"] = 14}, {["x"] = 2, ["y"] = 12, ["z"] = 37, ["param2"] = 16, ["name"] = "cblocks:slab_stonebrick_brown", ["param1"] = 14}, {["x"] = 2, ["y"] = 12, ["z"] = 50, ["param2"] = 16, ["name"] = "cblocks:micro_stonebrick_brown", ["param1"] = 14}, {["x"] = 2, ["y"] = 12, ["z"] = 51, ["param2"] = 16, ["name"] = "cblocks:slab_stonebrick_brown", ["param1"] = 14}, {["x"] = 2, ["y"] = 13, ["z"] = 2, ["param2"] = 16, ["name"] = "cblocks:slab_stonebrick_brown", ["param1"] = 10}, {["x"] = 2, ["y"] = 13, ["z"] = 3, ["param2"] = 5, ["name"] = "cblocks:micro_stonebrick_brown", ["param1"] = 11}, {["x"] = 2, ["y"] = 13, ["z"] = 4, ["param2"] = 1, ["name"] = "cblocks:panel_stonebrick_brown", ["param1"] = 12}, {["x"] = 2, ["y"] = 13, ["z"] = 5, ["param2"] = 1, ["name"] = "cblocks:panel_stonebrick_brown", ["param1"] = 13}, {["x"] = 2, ["y"] = 13, ["z"] = 7, ["param2"] = 1, ["name"] = "cblocks:panel_stonebrick_brown", ["param1"] = 14}, {["x"] = 2, ["y"] = 13, ["z"] = 8, ["param2"] = 1, ["name"] = "cblocks:panel_stonebrick_brown", ["param1"] = 14}, {["x"] = 2, ["y"] = 13, ["z"] = 10, ["param2"] = 1, ["name"] = "cblocks:panel_stonebrick_brown", ["param1"] = 14}, {["x"] = 2, ["y"] = 13, ["z"] = 11, ["param2"] = 1, ["name"] = "cblocks:panel_stonebrick_brown", ["param1"] = 14}, {["x"] = 2, ["y"] = 13, ["z"] = 13, ["param2"] = 1, ["name"] = "cblocks:panel_stonebrick_brown", ["param1"] = 14}, {["x"] = 2, ["y"] = 13, ["z"] = 14, ["param2"] = 1, ["name"] = "cblocks:panel_stonebrick_brown", ["param1"] = 14}, {["x"] = 2, ["y"] = 13, ["z"] = 16, ["param2"] = 16, ["name"] = "cblocks:slab_stonebrick_brown", ["param1"] = 14}, {["x"] = 2, ["y"] = 13, ["z"] = 17, ["param2"] = 5, ["name"] = "cblocks:micro_stonebrick_brown", ["param1"] = 14}, {["x"] = 2, ["y"] = 13, ["z"] = 18, ["name"] = "cblocks:slope_stonebrick_brown_half", ["param1"] = 14}, {["x"] = 2, ["y"] = 13, ["z"] = 19, ["param2"] = 2, ["name"] = "cblocks:slope_stonebrick_brown_half", ["param1"] = 14}, {["x"] = 2, ["y"] = 13, ["z"] = 21, ["name"] = "cblocks:slope_stonebrick_brown_half", ["param1"] = 14}, {["x"] = 2, ["y"] = 13, ["z"] = 22, ["param2"] = 2, ["name"] = "cblocks:slope_stonebrick_brown_half", ["param1"] = 14}, {["x"] = 2, ["y"] = 13, ["z"] = 24, ["name"] = "cblocks:slope_stonebrick_brown_half", ["param1"] = 14}, {["x"] = 2, ["y"] = 13, ["z"] = 25, ["param2"] = 2, ["name"] = "cblocks:slope_stonebrick_brown_half", ["param1"] = 14}, {["x"] = 2, ["y"] = 13, ["z"] = 28, ["name"] = "cblocks:slope_stonebrick_brown_half", ["param1"] = 14}, {["x"] = 2, ["y"] = 13, ["z"] = 29, ["param2"] = 2, ["name"] = "cblocks:slope_stonebrick_brown_half", ["param1"] = 14}, {["x"] = 2, ["y"] = 13, ["z"] = 31, ["name"] = "cblocks:slope_stonebrick_brown_half", ["param1"] = 14}, {["x"] = 2, ["y"] = 13, ["z"] = 32, ["param2"] = 2, ["name"] = "cblocks:slope_stonebrick_brown_half", ["param1"] = 14}, {["x"] = 2, ["y"] = 13, ["z"] = 34, ["name"] = "cblocks:slope_stonebrick_brown_half", ["param1"] = 14}, {["x"] = 2, ["y"] = 13, ["z"] = 35, ["param2"] = 2, ["name"] = "cblocks:slope_stonebrick_brown_half", ["param1"] = 14}, {["x"] = 2, ["y"] = 13, ["z"] = 36, ["param2"] = 16, ["name"] = "cblocks:micro_stonebrick_brown", ["param1"] = 14}, {["x"] = 2, ["y"] = 13, ["z"] = 37, ["param2"] = 16, ["name"] = "cblocks:slab_stonebrick_brown", ["param1"] = 14}, {["x"] = 2, ["y"] = 13, ["z"] = 39, ["param2"] = 1, ["name"] = "cblocks:panel_stonebrick_brown", ["param1"] = 14}, {["x"] = 2, ["y"] = 13, ["z"] = 40, ["param2"] = 1, ["name"] = "cblocks:panel_stonebrick_brown", ["param1"] = 14}, {["x"] = 2, ["y"] = 13, ["z"] = 42, ["param2"] = 1, ["name"] = "cblocks:panel_stonebrick_brown", ["param1"] = 14}, {["x"] = 2, ["y"] = 13, ["z"] = 43, ["param2"] = 1, ["name"] = "cblocks:panel_stonebrick_brown", ["param1"] = 14}, {["x"] = 2, ["y"] = 13, ["z"] = 45, ["param2"] = 1, ["name"] = "cblocks:panel_stonebrick_brown", ["param1"] = 14}, {["x"] = 2, ["y"] = 13, ["z"] = 46, ["param2"] = 1, ["name"] = "cblocks:panel_stonebrick_brown", ["param1"] = 14}, {["x"] = 2, ["y"] = 13, ["z"] = 48, ["param2"] = 1, ["name"] = "cblocks:panel_stonebrick_brown", ["param1"] = 14}, {["x"] = 2, ["y"] = 13, ["z"] = 49, ["param2"] = 1, ["name"] = "cblocks:panel_stonebrick_brown", ["param1"] = 14}, {["x"] = 2, ["y"] = 13, ["z"] = 50, ["param2"] = 16, ["name"] = "cblocks:micro_stonebrick_brown", ["param1"] = 14}, {["x"] = 2, ["y"] = 13, ["z"] = 51, ["param2"] = 16, ["name"] = "cblocks:slab_stonebrick_brown", ["param1"] = 14}, {["x"] = 2, ["y"] = 14, ["z"] = 2, ["param2"] = 16, ["name"] = "cblocks:slab_stonebrick_brown", ["param1"] = 10}, {["x"] = 2, ["y"] = 14, ["z"] = 3, ["param2"] = 5, ["name"] = "cblocks:micro_stonebrick_brown", ["param1"] = 11}, {["x"] = 2, ["y"] = 14, ["z"] = 16, ["param2"] = 16, ["name"] = "cblocks:slab_stonebrick_brown", ["param1"] = 14}, {["x"] = 2, ["y"] = 14, ["z"] = 17, ["param2"] = 2, ["name"] = "cblocks:micro_stonebrick_brown", ["param1"] = 14}, {["x"] = 2, ["y"] = 14, ["z"] = 18, ["param2"] = 23, ["name"] = "cblocks:panel_stonebrick_brown_2", ["param1"] = 14}, {["x"] = 2, ["y"] = 14, ["z"] = 19, ["param2"] = 23, ["name"] = "cblocks:panel_stonebrick_brown_2", ["param1"] = 14}, {["x"] = 2, ["y"] = 14, ["z"] = 21, ["param2"] = 23, ["name"] = "cblocks:panel_stonebrick_brown_2", ["param1"] = 14}, {["x"] = 2, ["y"] = 14, ["z"] = 22, ["param2"] = 23, ["name"] = "cblocks:panel_stonebrick_brown_2", ["param1"] = 14}, {["x"] = 2, ["y"] = 14, ["z"] = 24, ["param2"] = 23, ["name"] = "cblocks:panel_stonebrick_brown_2", ["param1"] = 14}, {["x"] = 2, ["y"] = 14, ["z"] = 25, ["param2"] = 23, ["name"] = "cblocks:panel_stonebrick_brown_2", ["param1"] = 14}, {["x"] = 2, ["y"] = 14, ["z"] = 28, ["param2"] = 23, ["name"] = "cblocks:panel_stonebrick_brown_2", ["param1"] = 14}, {["x"] = 2, ["y"] = 14, ["z"] = 29, ["param2"] = 23, ["name"] = "cblocks:panel_stonebrick_brown_2", ["param1"] = 14}, {["x"] = 2, ["y"] = 14, ["z"] = 31, ["param2"] = 23, ["name"] = "cblocks:panel_stonebrick_brown_2", ["param1"] = 14}, {["x"] = 2, ["y"] = 14, ["z"] = 32, ["param2"] = 23, ["name"] = "cblocks:panel_stonebrick_brown_2", ["param1"] = 14}, {["x"] = 2, ["y"] = 14, ["z"] = 34, ["param2"] = 23, ["name"] = "cblocks:panel_stonebrick_brown_2", ["param1"] = 14}, {["x"] = 2, ["y"] = 14, ["z"] = 35, ["param2"] = 23, ["name"] = "cblocks:panel_stonebrick_brown_2", ["param1"] = 14}, {["x"] = 2, ["y"] = 14, ["z"] = 36, ["param2"] = 16, ["name"] = "cblocks:micro_stonebrick_brown", ["param1"] = 14}, {["x"] = 2, ["y"] = 14, ["z"] = 37, ["param2"] = 16, ["name"] = "cblocks:slab_stonebrick_brown", ["param1"] = 14}, {["x"] = 2, ["y"] = 14, ["z"] = 50, ["param2"] = 16, ["name"] = "cblocks:micro_stonebrick_brown", ["param1"] = 14}, {["x"] = 2, ["y"] = 14, ["z"] = 51, ["param2"] = 16, ["name"] = "cblocks:slab_stonebrick_brown", ["param1"] = 14}, {["x"] = 2, ["y"] = 15, ["z"] = 2, ["param2"] = 16, ["name"] = "cblocks:slab_stonebrick_brown", ["param1"] = 10}, {["x"] = 2, ["y"] = 15, ["z"] = 3, ["param2"] = 5, ["name"] = "cblocks:micro_stonebrick_brown", ["param1"] = 11}, {["x"] = 2, ["y"] = 15, ["z"] = 16, ["param2"] = 16, ["name"] = "cblocks:slab_stonebrick_brown", ["param1"] = 14}, {["x"] = 2, ["y"] = 15, ["z"] = 17, ["param2"] = 5, ["name"] = "cblocks:micro_stonebrick_brown", ["param1"] = 14}, {["x"] = 2, ["y"] = 15, ["z"] = 36, ["param2"] = 16, ["name"] = "cblocks:micro_stonebrick_brown", ["param1"] = 14}, {["x"] = 2, ["y"] = 15, ["z"] = 37, ["param2"] = 16, ["name"] = "cblocks:slab_stonebrick_brown", ["param1"] = 14}, {["x"] = 2, ["y"] = 15, ["z"] = 50, ["param2"] = 16, ["name"] = "cblocks:micro_stonebrick_brown", ["param1"] = 14}, {["x"] = 2, ["y"] = 15, ["z"] = 51, ["param2"] = 16, ["name"] = "cblocks:slab_stonebrick_brown", ["param1"] = 14}, {["x"] = 2, ["y"] = 16, ["z"] = 2, ["param2"] = 16, ["name"] = "cblocks:slab_stonebrick_brown", ["param1"] = 10}, {["x"] = 2, ["y"] = 16, ["z"] = 3, ["param2"] = 5, ["name"] = "cblocks:micro_stonebrick_brown", ["param1"] = 11}, {["x"] = 2, ["y"] = 16, ["z"] = 16, ["param2"] = 16, ["name"] = "cblocks:slab_stonebrick_brown", ["param1"] = 14}, {["x"] = 2, ["y"] = 16, ["z"] = 17, ["param2"] = 5, ["name"] = "cblocks:micro_stonebrick_brown", ["param1"] = 14}, {["x"] = 2, ["y"] = 16, ["z"] = 36, ["param2"] = 16, ["name"] = "cblocks:micro_stonebrick_brown", ["param1"] = 14}, {["x"] = 2, ["y"] = 16, ["z"] = 37, ["param2"] = 16, ["name"] = "cblocks:slab_stonebrick_brown", ["param1"] = 14}, {["x"] = 2, ["y"] = 16, ["z"] = 50, ["param2"] = 16, ["name"] = "cblocks:micro_stonebrick_brown", ["param1"] = 14}, {["x"] = 2, ["y"] = 16, ["z"] = 51, ["param2"] = 16, ["name"] = "cblocks:slab_stonebrick_brown", ["param1"] = 14}, {["x"] = 2, ["y"] = 17, ["z"] = 2, ["param2"] = 16, ["name"] = "cblocks:slab_stonebrick_brown", ["param1"] = 10}, {["x"] = 2, ["y"] = 17, ["z"] = 3, ["param2"] = 5, ["name"] = "cblocks:micro_stonebrick_brown", ["param1"] = 11}, {["x"] = 2, ["y"] = 17, ["z"] = 16, ["param2"] = 16, ["name"] = "cblocks:slab_stonebrick_brown", ["param1"] = 14}, {["x"] = 2, ["y"] = 17, ["z"] = 17, ["param2"] = 5, ["name"] = "cblocks:micro_stonebrick_brown", ["param1"] = 14}, {["x"] = 2, ["y"] = 17, ["z"] = 36, ["param2"] = 16, ["name"] = "cblocks:micro_stonebrick_brown", ["param1"] = 14}, {["x"] = 2, ["y"] = 17, ["z"] = 37, ["param2"] = 16, ["name"] = "cblocks:slab_stonebrick_brown", ["param1"] = 14}, {["x"] = 2, ["y"] = 17, ["z"] = 50, ["param2"] = 16, ["name"] = "cblocks:micro_stonebrick_brown", ["param1"] = 14}, {["x"] = 2, ["y"] = 17, ["z"] = 51, ["param2"] = 16, ["name"] = "cblocks:slab_stonebrick_brown", ["param1"] = 14}, {["x"] = 2, ["y"] = 18, ["z"] = 2, ["param2"] = 16, ["name"] = "cblocks:slab_stonebrick_brown", ["param1"] = 10}, {["x"] = 2, ["y"] = 18, ["z"] = 3, ["param2"] = 5, ["name"] = "cblocks:micro_stonebrick_brown", ["param1"] = 11}, {["x"] = 2, ["y"] = 18, ["z"] = 16, ["param2"] = 16, ["name"] = "cblocks:slab_stonebrick_brown", ["param1"] = 14}, {["x"] = 2, ["y"] = 18, ["z"] = 17, ["param2"] = 2, ["name"] = "cblocks:micro_stonebrick_brown", ["param1"] = 14}, {["x"] = 2, ["y"] = 18, ["z"] = 36, ["param2"] = 16, ["name"] = "cblocks:micro_stonebrick_brown", ["param1"] = 14}, {["x"] = 2, ["y"] = 18, ["z"] = 37, ["param2"] = 16, ["name"] = "cblocks:slab_stonebrick_brown", ["param1"] = 14}, {["x"] = 2, ["y"] = 18, ["z"] = 50, ["param2"] = 16, ["name"] = "cblocks:micro_stonebrick_brown", ["param1"] = 14}, {["x"] = 2, ["y"] = 18, ["z"] = 51, ["param2"] = 16, ["name"] = "cblocks:slab_stonebrick_brown", ["param1"] = 14}, {["x"] = 2, ["y"] = 19, ["z"] = 2, ["param2"] = 16, ["name"] = "cblocks:slab_stonebrick_brown", ["param1"] = 10}, {["x"] = 2, ["y"] = 19, ["z"] = 3, ["param2"] = 5, ["name"] = "cblocks:micro_stonebrick_brown", ["param1"] = 11}, {["x"] = 2, ["y"] = 19, ["z"] = 4, ["name"] = "cblocks:slope_stonebrick_brown", ["param1"] = 12}, {["x"] = 2, ["y"] = 19, ["z"] = 5, ["param2"] = 2, ["name"] = "cblocks:slope_stonebrick_brown", ["param1"] = 13}, {["x"] = 2, ["y"] = 19, ["z"] = 7, ["name"] = "cblocks:slope_stonebrick_brown", ["param1"] = 14}, {["x"] = 2, ["y"] = 19, ["z"] = 8, ["param2"] = 2, ["name"] = "cblocks:slope_stonebrick_brown", ["param1"] = 14}, {["x"] = 2, ["y"] = 19, ["z"] = 10, ["name"] = "cblocks:slope_stonebrick_brown", ["param1"] = 14}, {["x"] = 2, ["y"] = 19, ["z"] = 11, ["param2"] = 2, ["name"] = "cblocks:slope_stonebrick_brown", ["param1"] = 14}, {["x"] = 2, ["y"] = 19, ["z"] = 13, ["name"] = "cblocks:slope_stonebrick_brown", ["param1"] = 14}, {["x"] = 2, ["y"] = 19, ["z"] = 14, ["param2"] = 2, ["name"] = "cblocks:slope_stonebrick_brown", ["param1"] = 14}, {["x"] = 2, ["y"] = 19, ["z"] = 16, ["param2"] = 16, ["name"] = "cblocks:slab_stonebrick_brown", ["param1"] = 14}, {["x"] = 2, ["y"] = 19, ["z"] = 17, ["param2"] = 5, ["name"] = "cblocks:micro_stonebrick_brown", ["param1"] = 14}, {["x"] = 2, ["y"] = 19, ["z"] = 36, ["param2"] = 16, ["name"] = "cblocks:micro_stonebrick_brown", ["param1"] = 14}, {["x"] = 2, ["y"] = 19, ["z"] = 37, ["param2"] = 16, ["name"] = "cblocks:slab_stonebrick_brown", ["param1"] = 14}, {["x"] = 2, ["y"] = 19, ["z"] = 39, ["name"] = "cblocks:slope_stonebrick_brown", ["param1"] = 14}, {["x"] = 2, ["y"] = 19, ["z"] = 40, ["param2"] = 2, ["name"] = "cblocks:slope_stonebrick_brown", ["param1"] = 14}, {["x"] = 2, ["y"] = 19, ["z"] = 42, ["name"] = "cblocks:slope_stonebrick_brown", ["param1"] = 14}, {["x"] = 2, ["y"] = 19, ["z"] = 43, ["param2"] = 2, ["name"] = "cblocks:slope_stonebrick_brown", ["param1"] = 14}, {["x"] = 2, ["y"] = 19, ["z"] = 45, ["name"] = "cblocks:slope_stonebrick_brown", ["param1"] = 14}, {["x"] = 2, ["y"] = 19, ["z"] = 46, ["param2"] = 2, ["name"] = "cblocks:slope_stonebrick_brown", ["param1"] = 14}, {["x"] = 2, ["y"] = 19, ["z"] = 48, ["name"] = "cblocks:slope_stonebrick_brown", ["param1"] = 14}, {["x"] = 2, ["y"] = 19, ["z"] = 49, ["param2"] = 2, ["name"] = "cblocks:slope_stonebrick_brown", ["param1"] = 14}, {["x"] = 2, ["y"] = 19, ["z"] = 50, ["param2"] = 16, ["name"] = "cblocks:micro_stonebrick_brown", ["param1"] = 14}, {["x"] = 2, ["y"] = 19, ["z"] = 51, ["param2"] = 16, ["name"] = "cblocks:slab_stonebrick_brown", ["param1"] = 14}, {["x"] = 2, ["y"] = 20, ["z"] = 2, ["param2"] = 16, ["name"] = "cblocks:slab_stonebrick_brown", ["param1"] = 10}, {["x"] = 2, ["y"] = 20, ["z"] = 3, ["param2"] = 5, ["name"] = "cblocks:micro_stonebrick_brown", ["param1"] = 11}, {["x"] = 2, ["y"] = 20, ["z"] = 16, ["param2"] = 16, ["name"] = "cblocks:slab_stonebrick_brown", ["param1"] = 14}, {["x"] = 2, ["y"] = 20, ["z"] = 17, ["param2"] = 5, ["name"] = "cblocks:micro_stonebrick_brown", ["param1"] = 14}, {["x"] = 2, ["y"] = 20, ["z"] = 18, ["param2"] = 22, ["name"] = "cblocks:stair_stonebrick_brown_right_half", ["param1"] = 14}, {["x"] = 2, ["y"] = 20, ["z"] = 19, ["param2"] = 20, ["name"] = "cblocks:stair_stonebrick_brown_half", ["param1"] = 14}, {["x"] = 2, ["y"] = 20, ["z"] = 21, ["param2"] = 22, ["name"] = "cblocks:stair_stonebrick_brown_right_half", ["param1"] = 14}, {["x"] = 2, ["y"] = 20, ["z"] = 22, ["param2"] = 20, ["name"] = "cblocks:stair_stonebrick_brown_half", ["param1"] = 14}, {["x"] = 2, ["y"] = 20, ["z"] = 24, ["param2"] = 22, ["name"] = "cblocks:stair_stonebrick_brown_right_half", ["param1"] = 14}, {["x"] = 2, ["y"] = 20, ["z"] = 25, ["param2"] = 20, ["name"] = "cblocks:stair_stonebrick_brown_half", ["param1"] = 14}, {["x"] = 2, ["y"] = 20, ["z"] = 28, ["param2"] = 22, ["name"] = "cblocks:stair_stonebrick_brown_right_half", ["param1"] = 14}, {["x"] = 2, ["y"] = 20, ["z"] = 29, ["param2"] = 20, ["name"] = "cblocks:stair_stonebrick_brown_half", ["param1"] = 14}, {["x"] = 2, ["y"] = 20, ["z"] = 31, ["param2"] = 22, ["name"] = "cblocks:stair_stonebrick_brown_right_half", ["param1"] = 14}, {["x"] = 2, ["y"] = 20, ["z"] = 32, ["param2"] = 20, ["name"] = "cblocks:stair_stonebrick_brown_half", ["param1"] = 14}, {["x"] = 2, ["y"] = 20, ["z"] = 34, ["param2"] = 22, ["name"] = "cblocks:stair_stonebrick_brown_right_half", ["param1"] = 14}, {["x"] = 2, ["y"] = 20, ["z"] = 35, ["param2"] = 20, ["name"] = "cblocks:stair_stonebrick_brown_half", ["param1"] = 14}, {["x"] = 2, ["y"] = 20, ["z"] = 36, ["param2"] = 16, ["name"] = "cblocks:micro_stonebrick_brown", ["param1"] = 14}, {["x"] = 2, ["y"] = 20, ["z"] = 37, ["param2"] = 16, ["name"] = "cblocks:slab_stonebrick_brown", ["param1"] = 14}, {["x"] = 2, ["y"] = 20, ["z"] = 50, ["param2"] = 16, ["name"] = "cblocks:micro_stonebrick_brown", ["param1"] = 14}, {["x"] = 2, ["y"] = 20, ["z"] = 51, ["param2"] = 16, ["name"] = "cblocks:slab_stonebrick_brown", ["param1"] = 14}, {["x"] = 2, ["y"] = 21, ["z"] = 2, ["param2"] = 16, ["name"] = "cblocks:slab_stonebrick_brown", ["param1"] = 10}, {["x"] = 2, ["y"] = 21, ["z"] = 3, ["param2"] = 5, ["name"] = "cblocks:micro_stonebrick_brown", ["param1"] = 11}, {["x"] = 2, ["y"] = 21, ["z"] = 16, ["param2"] = 16, ["name"] = "cblocks:slab_stonebrick_brown", ["param1"] = 14}, {["x"] = 2, ["y"] = 21, ["z"] = 17, ["param2"] = 5, ["name"] = "cblocks:micro_stonebrick_brown", ["param1"] = 14}, {["x"] = 2, ["y"] = 21, ["z"] = 18, ["param2"] = 18, ["name"] = "cblocks:panel_stonebrick_brown_4", ["param1"] = 14}, {["x"] = 2, ["y"] = 21, ["z"] = 19, ["param2"] = 16, ["name"] = "cblocks:panel_stonebrick_brown_4", ["param1"] = 14}, {["x"] = 2, ["y"] = 21, ["z"] = 21, ["param2"] = 18, ["name"] = "cblocks:panel_stonebrick_brown_4", ["param1"] = 14}, {["x"] = 2, ["y"] = 21, ["z"] = 22, ["param2"] = 16, ["name"] = "cblocks:panel_stonebrick_brown_4", ["param1"] = 14}, {["x"] = 2, ["y"] = 21, ["z"] = 24, ["param2"] = 18, ["name"] = "cblocks:panel_stonebrick_brown_4", ["param1"] = 14}, {["x"] = 2, ["y"] = 21, ["z"] = 25, ["param2"] = 16, ["name"] = "cblocks:panel_stonebrick_brown_4", ["param1"] = 14}, {["x"] = 2, ["y"] = 21, ["z"] = 28, ["param2"] = 18, ["name"] = "cblocks:panel_stonebrick_brown_4", ["param1"] = 14}, {["x"] = 2, ["y"] = 21, ["z"] = 29, ["param2"] = 16, ["name"] = "cblocks:panel_stonebrick_brown_4", ["param1"] = 14}, {["x"] = 2, ["y"] = 21, ["z"] = 31, ["param2"] = 18, ["name"] = "cblocks:panel_stonebrick_brown_4", ["param1"] = 14}, {["x"] = 2, ["y"] = 21, ["z"] = 32, ["param2"] = 16, ["name"] = "cblocks:panel_stonebrick_brown_4", ["param1"] = 14}, {["x"] = 2, ["y"] = 21, ["z"] = 34, ["param2"] = 18, ["name"] = "cblocks:panel_stonebrick_brown_4", ["param1"] = 14}, {["x"] = 2, ["y"] = 21, ["z"] = 35, ["param2"] = 16, ["name"] = "cblocks:panel_stonebrick_brown_4", ["param1"] = 14}, {["x"] = 2, ["y"] = 21, ["z"] = 36, ["param2"] = 16, ["name"] = "cblocks:micro_stonebrick_brown", ["param1"] = 14}, {["x"] = 2, ["y"] = 21, ["z"] = 37, ["param2"] = 16, ["name"] = "cblocks:slab_stonebrick_brown", ["param1"] = 14}, {["x"] = 2, ["y"] = 21, ["z"] = 50, ["param2"] = 16, ["name"] = "cblocks:micro_stonebrick_brown", ["param1"] = 14}, {["x"] = 2, ["y"] = 21, ["z"] = 51, ["param2"] = 16, ["name"] = "cblocks:slab_stonebrick_brown", ["param1"] = 14}, {["x"] = 2, ["y"] = 22, ["z"] = 2, ["param2"] = 16, ["name"] = "cblocks:slab_stonebrick_brown", ["param1"] = 10}, {["x"] = 2, ["y"] = 22, ["z"] = 3, ["param2"] = 5, ["name"] = "cblocks:micro_stonebrick_brown", ["param1"] = 11}, {["x"] = 2, ["y"] = 22, ["z"] = 16, ["param2"] = 16, ["name"] = "cblocks:slab_stonebrick_brown", ["param1"] = 14}, {["x"] = 2, ["y"] = 22, ["z"] = 17, ["param2"] = 2, ["name"] = "cblocks:micro_stonebrick_brown", ["param1"] = 14}, {["x"] = 2, ["y"] = 22, ["z"] = 18, ["param2"] = 18, ["name"] = "cblocks:panel_stonebrick_brown_4", ["param1"] = 14}, {["x"] = 2, ["y"] = 22, ["z"] = 19, ["param2"] = 16, ["name"] = "cblocks:panel_stonebrick_brown_4", ["param1"] = 14}, {["x"] = 2, ["y"] = 22, ["z"] = 21, ["param2"] = 18, ["name"] = "cblocks:panel_stonebrick_brown_4", ["param1"] = 14}, {["x"] = 2, ["y"] = 22, ["z"] = 22, ["param2"] = 16, ["name"] = "cblocks:panel_stonebrick_brown_4", ["param1"] = 14}, {["x"] = 2, ["y"] = 22, ["z"] = 24, ["param2"] = 18, ["name"] = "cblocks:panel_stonebrick_brown_4", ["param1"] = 14}, {["x"] = 2, ["y"] = 22, ["z"] = 25, ["param2"] = 16, ["name"] = "cblocks:panel_stonebrick_brown_4", ["param1"] = 14}, {["x"] = 2, ["y"] = 22, ["z"] = 28, ["param2"] = 18, ["name"] = "cblocks:panel_stonebrick_brown_4", ["param1"] = 14}, {["x"] = 2, ["y"] = 22, ["z"] = 29, ["param2"] = 16, ["name"] = "cblocks:panel_stonebrick_brown_4", ["param1"] = 14}, {["x"] = 2, ["y"] = 22, ["z"] = 31, ["param2"] = 18, ["name"] = "cblocks:panel_stonebrick_brown_4", ["param1"] = 14}, {["x"] = 2, ["y"] = 22, ["z"] = 32, ["param2"] = 16, ["name"] = "cblocks:panel_stonebrick_brown_4", ["param1"] = 14}, {["x"] = 2, ["y"] = 22, ["z"] = 34, ["param2"] = 18, ["name"] = "cblocks:panel_stonebrick_brown_4", ["param1"] = 14}, {["x"] = 2, ["y"] = 22, ["z"] = 35, ["param2"] = 16, ["name"] = "cblocks:panel_stonebrick_brown_4", ["param1"] = 14}, {["x"] = 2, ["y"] = 22, ["z"] = 36, ["param2"] = 16, ["name"] = "cblocks:micro_stonebrick_brown", ["param1"] = 14}, {["x"] = 2, ["y"] = 22, ["z"] = 37, ["param2"] = 16, ["name"] = "cblocks:slab_stonebrick_brown", ["param1"] = 14}, {["x"] = 2, ["y"] = 22, ["z"] = 50, ["param2"] = 16, ["name"] = "cblocks:micro_stonebrick_brown", ["param1"] = 14}, {["x"] = 2, ["y"] = 22, ["z"] = 51, ["param2"] = 16, ["name"] = "cblocks:slab_stonebrick_brown", ["param1"] = 14}, {["x"] = 2, ["y"] = 23, ["z"] = 2, ["param2"] = 16, ["name"] = "cblocks:slab_stonebrick_brown", ["param1"] = 10}, {["x"] = 2, ["y"] = 23, ["z"] = 3, ["param2"] = 5, ["name"] = "cblocks:micro_stonebrick_brown", ["param1"] = 11}, {["x"] = 2, ["y"] = 23, ["z"] = 16, ["param2"] = 16, ["name"] = "cblocks:slab_stonebrick_brown", ["param1"] = 14}, {["x"] = 2, ["y"] = 23, ["z"] = 17, ["param2"] = 5, ["name"] = "cblocks:micro_stonebrick_brown", ["param1"] = 14}, {["x"] = 2, ["y"] = 23, ["z"] = 18, ["param2"] = 22, ["name"] = "cblocks:stair_stonebrick_brown_right_half", ["param1"] = 14}, {["x"] = 2, ["y"] = 23, ["z"] = 19, ["param2"] = 20, ["name"] = "cblocks:stair_stonebrick_brown_half", ["param1"] = 14}, {["x"] = 2, ["y"] = 23, ["z"] = 21, ["param2"] = 22, ["name"] = "cblocks:stair_stonebrick_brown_right_half", ["param1"] = 14}, {["x"] = 2, ["y"] = 23, ["z"] = 22, ["param2"] = 20, ["name"] = "cblocks:stair_stonebrick_brown_half", ["param1"] = 14}, {["x"] = 2, ["y"] = 23, ["z"] = 24, ["param2"] = 22, ["name"] = "cblocks:stair_stonebrick_brown_right_half", ["param1"] = 14}, {["x"] = 2, ["y"] = 23, ["z"] = 25, ["param2"] = 20, ["name"] = "cblocks:stair_stonebrick_brown_half", ["param1"] = 14}, {["x"] = 2, ["y"] = 23, ["z"] = 28, ["param2"] = 22, ["name"] = "cblocks:stair_stonebrick_brown_right_half", ["param1"] = 14}, {["x"] = 2, ["y"] = 23, ["z"] = 29, ["param2"] = 20, ["name"] = "cblocks:stair_stonebrick_brown_half", ["param1"] = 14}, {["x"] = 2, ["y"] = 23, ["z"] = 31, ["param2"] = 22, ["name"] = "cblocks:stair_stonebrick_brown_right_half", ["param1"] = 14}, {["x"] = 2, ["y"] = 23, ["z"] = 32, ["param2"] = 20, ["name"] = "cblocks:stair_stonebrick_brown_half", ["param1"] = 14}, {["x"] = 2, ["y"] = 23, ["z"] = 34, ["param2"] = 22, ["name"] = "cblocks:stair_stonebrick_brown_right_half", ["param1"] = 14}, {["x"] = 2, ["y"] = 23, ["z"] = 35, ["param2"] = 20, ["name"] = "cblocks:stair_stonebrick_brown_half", ["param1"] = 14}, {["x"] = 2, ["y"] = 23, ["z"] = 36, ["param2"] = 16, ["name"] = "cblocks:micro_stonebrick_brown", ["param1"] = 14}, {["x"] = 2, ["y"] = 23, ["z"] = 37, ["param2"] = 16, ["name"] = "cblocks:slab_stonebrick_brown", ["param1"] = 14}, {["x"] = 2, ["y"] = 23, ["z"] = 50, ["param2"] = 16, ["name"] = "cblocks:micro_stonebrick_brown", ["param1"] = 14}, {["x"] = 2, ["y"] = 23, ["z"] = 51, ["param2"] = 16, ["name"] = "cblocks:slab_stonebrick_brown", ["param1"] = 14}, {["x"] = 2, ["y"] = 24, ["z"] = 2, ["param2"] = 16, ["name"] = "cblocks:slab_stonebrick_brown", ["param1"] = 10}, {["x"] = 2, ["y"] = 24, ["z"] = 3, ["param2"] = 5, ["name"] = "cblocks:micro_stonebrick_brown", ["param1"] = 11}, {["x"] = 2, ["y"] = 24, ["z"] = 16, ["param2"] = 16, ["name"] = "cblocks:slab_stonebrick_brown", ["param1"] = 14}, {["x"] = 2, ["y"] = 24, ["z"] = 17, ["param2"] = 5, ["name"] = "cblocks:micro_stonebrick_brown", ["param1"] = 14}, {["x"] = 2, ["y"] = 24, ["z"] = 18, ["name"] = "cblocks:slope_stonebrick_brown_half", ["param1"] = 14}, {["x"] = 2, ["y"] = 24, ["z"] = 19, ["param2"] = 2, ["name"] = "cblocks:slope_stonebrick_brown_half", ["param1"] = 14}, {["x"] = 2, ["y"] = 24, ["z"] = 21, ["name"] = "cblocks:slope_stonebrick_brown_half", ["param1"] = 14}, {["x"] = 2, ["y"] = 24, ["z"] = 22, ["param2"] = 2, ["name"] = "cblocks:slope_stonebrick_brown_half", ["param1"] = 14}, {["x"] = 2, ["y"] = 24, ["z"] = 24, ["name"] = "cblocks:slope_stonebrick_brown_half", ["param1"] = 14}, {["x"] = 2, ["y"] = 24, ["z"] = 25, ["param2"] = 2, ["name"] = "cblocks:slope_stonebrick_brown_half", ["param1"] = 14}, {["x"] = 2, ["y"] = 24, ["z"] = 28, ["name"] = "cblocks:slope_stonebrick_brown_half", ["param1"] = 14}, {["x"] = 2, ["y"] = 24, ["z"] = 29, ["param2"] = 2, ["name"] = "cblocks:slope_stonebrick_brown_half", ["param1"] = 14}, {["x"] = 2, ["y"] = 24, ["z"] = 31, ["name"] = "cblocks:slope_stonebrick_brown_half", ["param1"] = 14}, {["x"] = 2, ["y"] = 24, ["z"] = 32, ["param2"] = 2, ["name"] = "cblocks:slope_stonebrick_brown_half", ["param1"] = 14}, {["x"] = 2, ["y"] = 24, ["z"] = 34, ["name"] = "cblocks:slope_stonebrick_brown_half", ["param1"] = 14}, {["x"] = 2, ["y"] = 24, ["z"] = 35, ["param2"] = 2, ["name"] = "cblocks:slope_stonebrick_brown_half", ["param1"] = 14}, {["x"] = 2, ["y"] = 24, ["z"] = 36, ["param2"] = 16, ["name"] = "cblocks:micro_stonebrick_brown", ["param1"] = 14}, {["x"] = 2, ["y"] = 24, ["z"] = 37, ["param2"] = 16, ["name"] = "cblocks:slab_stonebrick_brown", ["param1"] = 14}, {["x"] = 2, ["y"] = 24, ["z"] = 50, ["param2"] = 16, ["name"] = "cblocks:micro_stonebrick_brown", ["param1"] = 14}, {["x"] = 2, ["y"] = 24, ["z"] = 51, ["param2"] = 16, ["name"] = "cblocks:slab_stonebrick_brown", ["param1"] = 14}, {["x"] = 2, ["y"] = 25, ["z"] = 2, ["param2"] = 16, ["name"] = "cblocks:slab_stonebrick_brown", ["param1"] = 10}, {["x"] = 2, ["y"] = 25, ["z"] = 3, ["param2"] = 5, ["name"] = "cblocks:micro_stonebrick_brown", ["param1"] = 11}, {["x"] = 2, ["y"] = 25, ["z"] = 16, ["param2"] = 16, ["name"] = "cblocks:slab_stonebrick_brown", ["param1"] = 14}, {["x"] = 2, ["y"] = 25, ["z"] = 17, ["param2"] = 5, ["name"] = "cblocks:micro_stonebrick_brown", ["param1"] = 14}, {["x"] = 2, ["y"] = 25, ["z"] = 36, ["param2"] = 16, ["name"] = "cblocks:micro_stonebrick_brown", ["param1"] = 14}, {["x"] = 2, ["y"] = 25, ["z"] = 37, ["param2"] = 16, ["name"] = "cblocks:slab_stonebrick_brown", ["param1"] = 14}, {["x"] = 2, ["y"] = 25, ["z"] = 50, ["param2"] = 16, ["name"] = "cblocks:micro_stonebrick_brown", ["param1"] = 14}, {["x"] = 2, ["y"] = 25, ["z"] = 51, ["param2"] = 18, ["name"] = "cblocks:slab_stonebrick_brown", ["param1"] = 14}, {["x"] = 2, ["y"] = 26, ["z"] = 2, ["param2"] = 16, ["name"] = "cblocks:slab_stonebrick_brown", ["param1"] = 10}, {["x"] = 2, ["y"] = 26, ["z"] = 3, ["param2"] = 23, ["name"] = "cblocks:stair_stonebrick_brown", ["param1"] = 11}, {["x"] = 2, ["y"] = 26, ["z"] = 4, ["param2"] = 23, ["name"] = "cblocks:stair_stonebrick_brown", ["param1"] = 12}, {["x"] = 2, ["y"] = 26, ["z"] = 5, ["param2"] = 23, ["name"] = "cblocks:stair_stonebrick_brown", ["param1"] = 13}, {["x"] = 2, ["y"] = 26, ["z"] = 6, ["param2"] = 23, ["name"] = "cblocks:stair_stonebrick_brown", ["param1"] = 14}, {["x"] = 2, ["y"] = 26, ["z"] = 7, ["param2"] = 23, ["name"] = "cblocks:stair_stonebrick_brown", ["param1"] = 14}, {["x"] = 2, ["y"] = 26, ["z"] = 8, ["param2"] = 23, ["name"] = "cblocks:stair_stonebrick_brown", ["param1"] = 14}, {["x"] = 2, ["y"] = 26, ["z"] = 9, ["param2"] = 23, ["name"] = "cblocks:stair_stonebrick_brown", ["param1"] = 14}, {["x"] = 2, ["y"] = 26, ["z"] = 10, ["param2"] = 23, ["name"] = "cblocks:stair_stonebrick_brown", ["param1"] = 14}, {["x"] = 2, ["y"] = 26, ["z"] = 11, ["param2"] = 23, ["name"] = "cblocks:stair_stonebrick_brown", ["param1"] = 14}, {["x"] = 2, ["y"] = 26, ["z"] = 12, ["param2"] = 23, ["name"] = "cblocks:stair_stonebrick_brown", ["param1"] = 14}, {["x"] = 2, ["y"] = 26, ["z"] = 13, ["param2"] = 23, ["name"] = "cblocks:stair_stonebrick_brown", ["param1"] = 14}, {["x"] = 2, ["y"] = 26, ["z"] = 14, ["param2"] = 23, ["name"] = "cblocks:stair_stonebrick_brown", ["param1"] = 14}, {["x"] = 2, ["y"] = 26, ["z"] = 15, ["param2"] = 23, ["name"] = "cblocks:stair_stonebrick_brown", ["param1"] = 14}, {["x"] = 2, ["y"] = 26, ["z"] = 16, ["param2"] = 16, ["name"] = "cblocks:slab_stonebrick_brown", ["param1"] = 14}, {["x"] = 2, ["y"] = 26, ["z"] = 17, ["param2"] = 23, ["name"] = "cblocks:stair_stonebrick_brown", ["param1"] = 14}, {["x"] = 2, ["y"] = 26, ["z"] = 18, ["param2"] = 23, ["name"] = "cblocks:stair_stonebrick_brown", ["param1"] = 14}, {["x"] = 2, ["y"] = 26, ["z"] = 19, ["param2"] = 23, ["name"] = "cblocks:stair_stonebrick_brown", ["param1"] = 14}, {["x"] = 2, ["y"] = 26, ["z"] = 20, ["param2"] = 23, ["name"] = "cblocks:stair_stonebrick_brown", ["param1"] = 14}, {["x"] = 2, ["y"] = 26, ["z"] = 21, ["param2"] = 23, ["name"] = "cblocks:stair_stonebrick_brown", ["param1"] = 14}, {["x"] = 2, ["y"] = 26, ["z"] = 22, ["param2"] = 23, ["name"] = "cblocks:stair_stonebrick_brown", ["param1"] = 14}, {["x"] = 2, ["y"] = 26, ["z"] = 23, ["param2"] = 23, ["name"] = "cblocks:stair_stonebrick_brown", ["param1"] = 14}, {["x"] = 2, ["y"] = 26, ["z"] = 24, ["param2"] = 23, ["name"] = "cblocks:stair_stonebrick_brown", ["param1"] = 14}, {["x"] = 2, ["y"] = 26, ["z"] = 25, ["param2"] = 23, ["name"] = "cblocks:stair_stonebrick_brown", ["param1"] = 14}, {["x"] = 2, ["y"] = 26, ["z"] = 26, ["param2"] = 23, ["name"] = "cblocks:stair_stonebrick_brown", ["param1"] = 14}, {["x"] = 2, ["y"] = 26, ["z"] = 27, ["param2"] = 23, ["name"] = "cblocks:stair_stonebrick_brown", ["param1"] = 14}, {["x"] = 2, ["y"] = 26, ["z"] = 28, ["param2"] = 23, ["name"] = "cblocks:stair_stonebrick_brown", ["param1"] = 14}, {["x"] = 2, ["y"] = 26, ["z"] = 29, ["param2"] = 23, ["name"] = "cblocks:stair_stonebrick_brown", ["param1"] = 14}, {["x"] = 2, ["y"] = 26, ["z"] = 30, ["param2"] = 23, ["name"] = "cblocks:stair_stonebrick_brown", ["param1"] = 14}, {["x"] = 2, ["y"] = 26, ["z"] = 31, ["param2"] = 23, ["name"] = "cblocks:stair_stonebrick_brown", ["param1"] = 14}, {["x"] = 2, ["y"] = 26, ["z"] = 32, ["param2"] = 23, ["name"] = "cblocks:stair_stonebrick_brown", ["param1"] = 14}, {["x"] = 2, ["y"] = 26, ["z"] = 33, ["param2"] = 23, ["name"] = "cblocks:stair_stonebrick_brown", ["param1"] = 14}, {["x"] = 2, ["y"] = 26, ["z"] = 34, ["param2"] = 23, ["name"] = "cblocks:stair_stonebrick_brown", ["param1"] = 14}, {["x"] = 2, ["y"] = 26, ["z"] = 35, ["param2"] = 23, ["name"] = "cblocks:stair_stonebrick_brown", ["param1"] = 14}, {["x"] = 2, ["y"] = 26, ["z"] = 36, ["param2"] = 23, ["name"] = "cblocks:stair_stonebrick_brown", ["param1"] = 14}, {["x"] = 2, ["y"] = 26, ["z"] = 37, ["param2"] = 23, ["name"] = "cblocks:stair_stonebrick_brown", ["param1"] = 14}, {["x"] = 2, ["y"] = 26, ["z"] = 38, ["param2"] = 23, ["name"] = "cblocks:stair_stonebrick_brown", ["param1"] = 14}, {["x"] = 2, ["y"] = 26, ["z"] = 39, ["param2"] = 23, ["name"] = "cblocks:stair_stonebrick_brown", ["param1"] = 14}, {["x"] = 2, ["y"] = 26, ["z"] = 40, ["param2"] = 23, ["name"] = "cblocks:stair_stonebrick_brown", ["param1"] = 14}, {["x"] = 2, ["y"] = 26, ["z"] = 41, ["param2"] = 23, ["name"] = "cblocks:stair_stonebrick_brown", ["param1"] = 14}, {["x"] = 2, ["y"] = 26, ["z"] = 42, ["param2"] = 23, ["name"] = "cblocks:stair_stonebrick_brown", ["param1"] = 14}, {["x"] = 2, ["y"] = 26, ["z"] = 43, ["param2"] = 23, ["name"] = "cblocks:stair_stonebrick_brown", ["param1"] = 14}, {["x"] = 2, ["y"] = 26, ["z"] = 44, ["param2"] = 23, ["name"] = "cblocks:stair_stonebrick_brown", ["param1"] = 14}, {["x"] = 2, ["y"] = 26, ["z"] = 45, ["param2"] = 23, ["name"] = "cblocks:stair_stonebrick_brown", ["param1"] = 14}, {["x"] = 2, ["y"] = 26, ["z"] = 46, ["param2"] = 23, ["name"] = "cblocks:stair_stonebrick_brown", ["param1"] = 14}, {["x"] = 2, ["y"] = 26, ["z"] = 47, ["param2"] = 23, ["name"] = "cblocks:stair_stonebrick_brown", ["param1"] = 14}, {["x"] = 2, ["y"] = 26, ["z"] = 48, ["param2"] = 23, ["name"] = "cblocks:stair_stonebrick_brown", ["param1"] = 14}, {["x"] = 2, ["y"] = 26, ["z"] = 49, ["param2"] = 23, ["name"] = "cblocks:stair_stonebrick_brown", ["param1"] = 14}, {["x"] = 2, ["y"] = 26, ["z"] = 50, ["param2"] = 23, ["name"] = "cblocks:stair_stonebrick_brown", ["param1"] = 14}, {["x"] = 2, ["y"] = 26, ["z"] = 51, ["param2"] = 16, ["name"] = "cblocks:slab_stonebrick_brown", ["param1"] = 14}, {["x"] = 2, ["y"] = 27, ["z"] = 2, ["param2"] = 1, ["name"] = "cblocks:stonebrick_brown", ["param1"] = 10}, {["x"] = 2, ["y"] = 27, ["z"] = 3, ["param2"] = 14, ["name"] = "cblocks:panel_stonebrick_brown", ["param1"] = 11}, {["x"] = 2, ["y"] = 27, ["z"] = 4, ["param2"] = 14, ["name"] = "cblocks:panel_stonebrick_brown", ["param1"] = 12}, {["x"] = 2, ["y"] = 27, ["z"] = 5, ["param2"] = 14, ["name"] = "cblocks:panel_stonebrick_brown", ["param1"] = 13}, {["x"] = 2, ["y"] = 27, ["z"] = 6, ["param2"] = 14, ["name"] = "cblocks:panel_stonebrick_brown", ["param1"] = 14}, {["x"] = 2, ["y"] = 27, ["z"] = 7, ["param2"] = 14, ["name"] = "cblocks:panel_stonebrick_brown", ["param1"] = 14}, {["x"] = 2, ["y"] = 27, ["z"] = 8, ["param2"] = 14, ["name"] = "cblocks:panel_stonebrick_brown", ["param1"] = 14}, {["x"] = 2, ["y"] = 27, ["z"] = 9, ["param2"] = 1, ["name"] = "cblocks:stonebrick_brown", ["param1"] = 14}, {["x"] = 2, ["y"] = 27, ["z"] = 10, ["param2"] = 11, ["name"] = "cblocks:panel_stonebrick_brown", ["param1"] = 14}, {["x"] = 2, ["y"] = 27, ["z"] = 11, ["param2"] = 11, ["name"] = "cblocks:panel_stonebrick_brown", ["param1"] = 14}, {["x"] = 2, ["y"] = 27, ["z"] = 12, ["param2"] = 11, ["name"] = "cblocks:panel_stonebrick_brown", ["param1"] = 14}, {["x"] = 2, ["y"] = 27, ["z"] = 13, ["param2"] = 11, ["name"] = "cblocks:panel_stonebrick_brown", ["param1"] = 14}, {["x"] = 2, ["y"] = 27, ["z"] = 14, ["param2"] = 11, ["name"] = "cblocks:panel_stonebrick_brown", ["param1"] = 14}, {["x"] = 2, ["y"] = 27, ["z"] = 15, ["param2"] = 12, ["name"] = "cblocks:panel_stonebrick_brown", ["param1"] = 14}, {["x"] = 2, ["y"] = 27, ["z"] = 16, ["param2"] = 16, ["name"] = "cblocks:slab_stonebrick_brown", ["param1"] = 14}, {["x"] = 2, ["y"] = 27, ["z"] = 37, ["param2"] = 16, ["name"] = "cblocks:slab_stonebrick_brown", ["param1"] = 14}, {["x"] = 2, ["y"] = 27, ["z"] = 38, ["param2"] = 14, ["name"] = "cblocks:panel_stonebrick_brown", ["param1"] = 14}, {["x"] = 2, ["y"] = 27, ["z"] = 39, ["param2"] = 14, ["name"] = "cblocks:panel_stonebrick_brown", ["param1"] = 14}, {["x"] = 2, ["y"] = 27, ["z"] = 40, ["param2"] = 14, ["name"] = "cblocks:panel_stonebrick_brown", ["param1"] = 14}, {["x"] = 2, ["y"] = 27, ["z"] = 41, ["param2"] = 14, ["name"] = "cblocks:panel_stonebrick_brown", ["param1"] = 14}, {["x"] = 2, ["y"] = 27, ["z"] = 42, ["param2"] = 14, ["name"] = "cblocks:panel_stonebrick_brown", ["param1"] = 14}, {["x"] = 2, ["y"] = 27, ["z"] = 43, ["param2"] = 14, ["name"] = "cblocks:panel_stonebrick_brown", ["param1"] = 14}, {["x"] = 2, ["y"] = 27, ["z"] = 44, ["param2"] = 1, ["name"] = "cblocks:stonebrick_brown", ["param1"] = 14}, {["x"] = 2, ["y"] = 27, ["z"] = 45, ["param2"] = 11, ["name"] = "cblocks:panel_stonebrick_brown", ["param1"] = 14}, {["x"] = 2, ["y"] = 27, ["z"] = 46, ["param2"] = 11, ["name"] = "cblocks:panel_stonebrick_brown", ["param1"] = 14}, {["x"] = 2, ["y"] = 27, ["z"] = 47, ["param2"] = 11, ["name"] = "cblocks:panel_stonebrick_brown", ["param1"] = 14}, {["x"] = 2, ["y"] = 27, ["z"] = 48, ["param2"] = 11, ["name"] = "cblocks:panel_stonebrick_brown", ["param1"] = 14}, {["x"] = 2, ["y"] = 27, ["z"] = 49, ["param2"] = 11, ["name"] = "cblocks:panel_stonebrick_brown", ["param1"] = 14}, {["x"] = 2, ["y"] = 27, ["z"] = 50, ["param2"] = 11, ["name"] = "cblocks:panel_stonebrick_brown", ["param1"] = 14}, {["x"] = 2, ["y"] = 27, ["z"] = 51, ["param2"] = 1, ["name"] = "cblocks:stonebrick_brown", ["param1"] = 14}, {["x"] = 2, ["y"] = 28, ["z"] = 2, ["param2"] = 1, ["name"] = "cblocks:stonebrick_blue", ["param1"] = 10}, {["x"] = 2, ["y"] = 28, ["z"] = 3, ["param2"] = 3, ["name"] = "cblocks:panel_stonebrick_brown_2", ["param1"] = 11}, {["x"] = 2, ["y"] = 28, ["z"] = 4, ["param2"] = 3, ["name"] = "cblocks:panel_stonebrick_brown_2", ["param1"] = 12}, {["x"] = 2, ["y"] = 28, ["z"] = 5, ["param2"] = 3, ["name"] = "cblocks:panel_stonebrick_brown_2", ["param1"] = 13}, {["x"] = 2, ["y"] = 28, ["z"] = 6, ["param2"] = 3, ["name"] = "cblocks:panel_stonebrick_brown_2", ["param1"] = 14}, {["x"] = 2, ["y"] = 28, ["z"] = 7, ["param2"] = 3, ["name"] = "cblocks:panel_stonebrick_brown_2", ["param1"] = 14}, {["x"] = 2, ["y"] = 28, ["z"] = 8, ["param2"] = 3, ["name"] = "cblocks:panel_stonebrick_brown_2", ["param1"] = 14}, {["x"] = 2, ["y"] = 28, ["z"] = 9, ["param2"] = 1, ["name"] = "cblocks:slab_stonebrick_brown", ["param1"] = 14}, {["x"] = 2, ["y"] = 28, ["z"] = 10, ["param2"] = 3, ["name"] = "cblocks:panel_stonebrick_brown_2", ["param1"] = 14}, {["x"] = 2, ["y"] = 28, ["z"] = 11, ["param2"] = 3, ["name"] = "cblocks:panel_stonebrick_brown_2", ["param1"] = 14}, {["x"] = 2, ["y"] = 28, ["z"] = 12, ["param2"] = 3, ["name"] = "cblocks:panel_stonebrick_brown_2", ["param1"] = 14}, {["x"] = 2, ["y"] = 28, ["z"] = 13, ["param2"] = 3, ["name"] = "cblocks:panel_stonebrick_brown_2", ["param1"] = 14}, {["x"] = 2, ["y"] = 28, ["z"] = 14, ["param2"] = 3, ["name"] = "cblocks:panel_stonebrick_brown_2", ["param1"] = 14}, {["x"] = 2, ["y"] = 28, ["z"] = 15, ["param2"] = 3, ["name"] = "cblocks:panel_stonebrick_brown_2", ["param1"] = 14}, {["x"] = 2, ["y"] = 28, ["z"] = 16, ["param2"] = 16, ["name"] = "cblocks:slab_stonebrick_brown", ["param1"] = 14}, {["x"] = 2, ["y"] = 28, ["z"] = 37, ["param2"] = 16, ["name"] = "cblocks:slab_stonebrick_brown", ["param1"] = 14}, {["x"] = 2, ["y"] = 28, ["z"] = 38, ["param2"] = 3, ["name"] = "cblocks:panel_stonebrick_brown_2", ["param1"] = 14}, {["x"] = 2, ["y"] = 28, ["z"] = 39, ["param2"] = 3, ["name"] = "cblocks:panel_stonebrick_brown_2", ["param1"] = 14}, {["x"] = 2, ["y"] = 28, ["z"] = 40, ["param2"] = 3, ["name"] = "cblocks:panel_stonebrick_brown_2", ["param1"] = 14}, {["x"] = 2, ["y"] = 28, ["z"] = 41, ["param2"] = 3, ["name"] = "cblocks:panel_stonebrick_brown_2", ["param1"] = 14}, {["x"] = 2, ["y"] = 28, ["z"] = 42, ["param2"] = 3, ["name"] = "cblocks:panel_stonebrick_brown_2", ["param1"] = 14}, {["x"] = 2, ["y"] = 28, ["z"] = 43, ["param2"] = 3, ["name"] = "cblocks:panel_stonebrick_brown_2", ["param1"] = 14}, {["x"] = 2, ["y"] = 28, ["z"] = 44, ["param2"] = 1, ["name"] = "cblocks:slab_stonebrick_brown", ["param1"] = 14}, {["x"] = 2, ["y"] = 28, ["z"] = 45, ["param2"] = 3, ["name"] = "cblocks:panel_stonebrick_brown_2", ["param1"] = 14}, {["x"] = 2, ["y"] = 28, ["z"] = 46, ["param2"] = 3, ["name"] = "cblocks:panel_stonebrick_brown_2", ["param1"] = 14}, {["x"] = 2, ["y"] = 28, ["z"] = 47, ["param2"] = 3, ["name"] = "cblocks:panel_stonebrick_brown_2", ["param1"] = 14}, {["x"] = 2, ["y"] = 28, ["z"] = 48, ["param2"] = 3, ["name"] = "cblocks:panel_stonebrick_brown_2", ["param1"] = 14}, {["x"] = 2, ["y"] = 28, ["z"] = 49, ["param2"] = 3, ["name"] = "cblocks:panel_stonebrick_brown_2", ["param1"] = 14}, {["x"] = 2, ["y"] = 28, ["z"] = 50, ["param2"] = 3, ["name"] = "cblocks:panel_stonebrick_brown_2", ["param1"] = 14}, {["x"] = 2, ["y"] = 28, ["z"] = 51, ["param2"] = 1, ["name"] = "cblocks:stonebrick_blue", ["param1"] = 14}, {["x"] = 2, ["y"] = 29, ["z"] = 2, ["param2"] = 1, ["name"] = "cblocks:stonebrick_blue", ["param1"] = 11}, {["x"] = 2, ["y"] = 29, ["z"] = 16, ["param2"] = 16, ["name"] = "cblocks:slab_stonebrick_brown", ["param1"] = 14}, {["x"] = 2, ["y"] = 29, ["z"] = 37, ["param2"] = 16, ["name"] = "cblocks:slab_stonebrick_brown", ["param1"] = 14}, {["x"] = 2, ["y"] = 29, ["z"] = 51, ["param2"] = 1, ["name"] = "cblocks:stonebrick_blue", ["param1"] = 14}, {["x"] = 2, ["y"] = 30, ["z"] = 2, ["param2"] = 18, ["name"] = "cblocks:panel_stonebrick_blue", ["param1"] = 11}, {["x"] = 2, ["y"] = 30, ["z"] = 16, ["param2"] = 16, ["name"] = "cblocks:slab_stonebrick_brown", ["param1"] = 14}, {["x"] = 2, ["y"] = 30, ["z"] = 37, ["param2"] = 16, ["name"] = "cblocks:slab_stonebrick_brown", ["param1"] = 14}, {["x"] = 2, ["y"] = 30, ["z"] = 51, ["param2"] = 16, ["name"] = "cblocks:panel_stonebrick_blue", ["param1"] = 14}, {["x"] = 2, ["y"] = 31, ["z"] = 2, ["param2"] = 18, ["name"] = "cblocks:panel_stonebrick_blue", ["param1"] = 11}, {["x"] = 2, ["y"] = 31, ["z"] = 16, ["param2"] = 16, ["name"] = "cblocks:slab_stonebrick_brown", ["param1"] = 14}, {["x"] = 2, ["y"] = 31, ["z"] = 37, ["param2"] = 16, ["name"] = "cblocks:slab_stonebrick_brown", ["param1"] = 14}, {["x"] = 2, ["y"] = 31, ["z"] = 51, ["param2"] = 16, ["name"] = "cblocks:panel_stonebrick_blue", ["param1"] = 14}, {["x"] = 2, ["y"] = 32, ["z"] = 16, ["param2"] = 16, ["name"] = "cblocks:slab_stonebrick_brown", ["param1"] = 14}, {["x"] = 2, ["y"] = 32, ["z"] = 37, ["param2"] = 16, ["name"] = "cblocks:slab_stonebrick_brown", ["param1"] = 14}, {["x"] = 2, ["y"] = 33, ["z"] = 16, ["param2"] = 16, ["name"] = "cblocks:slab_stonebrick_brown", ["param1"] = 14}, {["x"] = 2, ["y"] = 33, ["z"] = 37, ["param2"] = 16, ["name"] = "cblocks:slab_stonebrick_brown", ["param1"] = 14}, {["x"] = 2, ["y"] = 34, ["z"] = 16, ["param2"] = 16, ["name"] = "cblocks:slab_stonebrick_brown", ["param1"] = 14}, {["x"] = 2, ["y"] = 34, ["z"] = 37, ["param2"] = 16, ["name"] = "cblocks:slab_stonebrick_brown", ["param1"] = 14}, {["x"] = 2, ["y"] = 35, ["z"] = 16, ["param2"] = 16, ["name"] = "cblocks:slab_stonebrick_brown", ["param1"] = 14}, {["x"] = 2, ["y"] = 35, ["z"] = 37, ["param2"] = 16, ["name"] = "cblocks:slab_stonebrick_brown", ["param1"] = 14}, {["x"] = 2, ["y"] = 43, ["z"] = 23, ["param2"] = 16, ["name"] = "cblocks:panel_stonebrick_brown_4", ["param1"] = 14}, {["x"] = 2, ["y"] = 43, ["z"] = 24, ["param2"] = 16, ["name"] = "cblocks:panel_stonebrick_brown_4", ["param1"] = 14}, {["x"] = 2, ["y"] = 43, ["z"] = 25, ["param2"] = 16, ["name"] = "cblocks:panel_stonebrick_brown_4", ["param1"] = 14}, {["x"] = 2, ["y"] = 43, ["z"] = 26, ["param2"] = 16, ["name"] = "cblocks:panel_stonebrick_brown_4", ["param1"] = 14}, {["x"] = 2, ["y"] = 43, ["z"] = 27, ["param2"] = 18, ["name"] = "cblocks:panel_stonebrick_brown_4", ["param1"] = 14}, {["x"] = 2, ["y"] = 43, ["z"] = 28, ["param2"] = 18, ["name"] = "cblocks:panel_stonebrick_brown_4", ["param1"] = 14}, {["x"] = 2, ["y"] = 43, ["z"] = 29, ["param2"] = 18, ["name"] = "cblocks:panel_stonebrick_brown_4", ["param1"] = 14}, {["x"] = 2, ["y"] = 43, ["z"] = 30, ["param2"] = 18, ["name"] = "cblocks:panel_stonebrick_brown_4", ["param1"] = 14}, {["x"] = 2, ["y"] = 44, ["z"] = 19, ["param2"] = 16, ["name"] = "cblocks:panel_stonebrick_brown", ["param1"] = 14}, {["x"] = 2, ["y"] = 44, ["z"] = 20, ["param2"] = 18, ["name"] = "cblocks:slab_stonebrick_brown", ["param1"] = 14}, {["x"] = 2, ["y"] = 44, ["z"] = 21, ["param2"] = 1, ["name"] = "cblocks:panel_stonebrick_brown", ["param1"] = 14}, {["x"] = 2, ["y"] = 44, ["z"] = 22, ["param2"] = 1, ["name"] = "cblocks:panel_stonebrick_brown", ["param1"] = 14}, {["x"] = 2, ["y"] = 44, ["z"] = 23, ["param2"] = 1, ["name"] = "cblocks:panel_stonebrick_brown", ["param1"] = 14}, {["x"] = 2, ["y"] = 44, ["z"] = 24, ["param2"] = 1, ["name"] = "cblocks:panel_stonebrick_brown", ["param1"] = 14}, {["x"] = 2, ["y"] = 44, ["z"] = 25, ["param2"] = 1, ["name"] = "cblocks:panel_stonebrick_brown", ["param1"] = 14}, {["x"] = 2, ["y"] = 44, ["z"] = 26, ["param2"] = 1, ["name"] = "cblocks:panel_stonebrick_brown", ["param1"] = 14}, {["x"] = 2, ["y"] = 44, ["z"] = 27, ["param2"] = 1, ["name"] = "cblocks:panel_stonebrick_brown", ["param1"] = 14}, {["x"] = 2, ["y"] = 44, ["z"] = 28, ["param2"] = 1, ["name"] = "cblocks:panel_stonebrick_brown", ["param1"] = 14}, {["x"] = 2, ["y"] = 44, ["z"] = 29, ["param2"] = 1, ["name"] = "cblocks:panel_stonebrick_brown", ["param1"] = 14}, {["x"] = 2, ["y"] = 44, ["z"] = 30, ["param2"] = 1, ["name"] = "cblocks:panel_stonebrick_brown", ["param1"] = 14}, {["x"] = 2, ["y"] = 44, ["z"] = 31, ["param2"] = 1, ["name"] = "cblocks:panel_stonebrick_brown", ["param1"] = 14}, {["x"] = 2, ["y"] = 44, ["z"] = 32, ["param2"] = 1, ["name"] = "cblocks:panel_stonebrick_brown", ["param1"] = 14}, {["x"] = 2, ["y"] = 44, ["z"] = 33, ["param2"] = 16, ["name"] = "cblocks:slab_stonebrick_brown", ["param1"] = 14}, {["x"] = 2, ["y"] = 44, ["z"] = 34, ["param2"] = 5, ["name"] = "cblocks:panel_stonebrick_brown", ["param1"] = 14}, {["x"] = 2, ["y"] = 45, ["z"] = 19, ["name"] = "cblocks:slab_stonebrick_blue_1", ["param1"] = 14}, {["x"] = 2, ["y"] = 45, ["z"] = 20, ["name"] = "cblocks:slab_stonebrick_blue_1", ["param1"] = 14}, {["x"] = 2, ["y"] = 45, ["z"] = 21, ["name"] = "cblocks:slab_stonebrick_blue_1", ["param1"] = 14}, {["x"] = 2, ["y"] = 45, ["z"] = 22, ["name"] = "cblocks:slab_stonebrick_blue_1", ["param1"] = 14}, {["x"] = 2, ["y"] = 45, ["z"] = 23, ["name"] = "cblocks:slope_stonebrick_blue", ["param1"] = 14}, {["x"] = 2, ["y"] = 45, ["z"] = 24, ["param2"] = 22, ["name"] = "cblocks:slope_stonebrick_blue", ["param1"] = 14}, {["x"] = 2, ["y"] = 45, ["z"] = 29, ["param2"] = 20, ["name"] = "cblocks:slope_stonebrick_blue", ["param1"] = 14}, {["x"] = 2, ["y"] = 45, ["z"] = 30, ["param2"] = 2, ["name"] = "cblocks:slope_stonebrick_blue", ["param1"] = 14}, {["x"] = 2, ["y"] = 45, ["z"] = 31, ["name"] = "cblocks:slab_stonebrick_blue_1", ["param1"] = 14}, {["x"] = 2, ["y"] = 45, ["z"] = 32, ["name"] = "cblocks:slab_stonebrick_blue_1", ["param1"] = 14}, {["x"] = 2, ["y"] = 45, ["z"] = 33, ["name"] = "cblocks:slab_stonebrick_blue_1", ["param1"] = 14}, {["x"] = 2, ["y"] = 45, ["z"] = 34, ["name"] = "cblocks:slab_stonebrick_blue_1", ["param1"] = 14}, {["x"] = 2, ["y"] = 46, ["z"] = 24, ["name"] = "cblocks:slope_stonebrick_blue", ["param1"] = 14}, {["x"] = 2, ["y"] = 46, ["z"] = 25, ["param2"] = 22, ["name"] = "cblocks:slope_stonebrick_blue", ["param1"] = 14}, {["x"] = 2, ["y"] = 46, ["z"] = 28, ["param2"] = 20, ["name"] = "cblocks:slope_stonebrick_blue", ["param1"] = 14}, {["x"] = 2, ["y"] = 46, ["z"] = 29, ["param2"] = 2, ["name"] = "cblocks:slope_stonebrick_blue", ["param1"] = 14}, {["x"] = 2, ["y"] = 47, ["z"] = 25, ["name"] = "cblocks:slope_stonebrick_blue", ["param1"] = 14}, {["x"] = 2, ["y"] = 47, ["z"] = 26, ["param2"] = 22, ["name"] = "cblocks:slope_stonebrick_blue", ["param1"] = 14}, {["x"] = 2, ["y"] = 47, ["z"] = 27, ["param2"] = 20, ["name"] = "cblocks:slope_stonebrick_blue", ["param1"] = 14}, {["x"] = 2, ["y"] = 47, ["z"] = 28, ["param2"] = 2, ["name"] = "cblocks:slope_stonebrick_blue", ["param1"] = 14}, {["x"] = 2, ["y"] = 48, ["z"] = 26, ["name"] = "cblocks:slope_stonebrick_blue", ["param1"] = 14}, {["x"] = 2, ["y"] = 48, ["z"] = 27, ["param2"] = 2, ["name"] = "cblocks:slope_stonebrick_blue", ["param1"] = 14}, {["x"] = 3, ["y"] = 0, ["z"] = 0, ["name"] = "default:dirt_with_grass", ["param1"] = 28}, {["x"] = 3, ["y"] = 0, ["z"] = 1, ["name"] = "default:dirt_with_grass", ["param1"] = 28}, {["x"] = 3, ["y"] = 0, ["z"] = 2, ["name"] = "default:dirt_with_grass", ["param1"] = 28}, {["x"] = 3, ["y"] = 0, ["z"] = 3, ["name"] = "default:dirt_with_grass", ["param1"] = 28}, {["x"] = 3, ["y"] = 0, ["z"] = 4, ["name"] = "default:dirt_with_grass", ["param1"] = 28}, {["x"] = 3, ["y"] = 0, ["z"] = 5, ["name"] = "default:dirt_with_grass", ["param1"] = 28}, {["x"] = 3, ["y"] = 0, ["z"] = 6, ["name"] = "default:dirt_with_grass", ["param1"] = 28}, {["x"] = 3, ["y"] = 0, ["z"] = 7, ["name"] = "default:dirt_with_grass", ["param1"] = 28}, {["x"] = 3, ["y"] = 0, ["z"] = 8, ["name"] = "default:dirt_with_grass", ["param1"] = 28}, {["x"] = 3, ["y"] = 0, ["z"] = 9, ["name"] = "default:dirt_with_grass", ["param1"] = 28}, {["x"] = 3, ["y"] = 0, ["z"] = 10, ["name"] = "default:dirt_with_grass", ["param1"] = 28}, {["x"] = 3, ["y"] = 0, ["z"] = 11, ["name"] = "default:dirt_with_grass", ["param1"] = 28}, {["x"] = 3, ["y"] = 0, ["z"] = 12, ["name"] = "default:dirt_with_grass", ["param1"] = 28}, {["x"] = 3, ["y"] = 0, ["z"] = 13, ["name"] = "default:dirt_with_grass", ["param1"] = 28}, {["x"] = 3, ["y"] = 0, ["z"] = 14, ["name"] = "default:dirt_with_grass", ["param1"] = 28}, {["x"] = 3, ["y"] = 0, ["z"] = 15, ["name"] = "default:dirt_with_grass", ["param1"] = 28}, {["x"] = 3, ["y"] = 0, ["z"] = 16, ["name"] = "default:dirt_with_grass", ["param1"] = 28}, {["x"] = 3, ["y"] = 0, ["z"] = 17, ["name"] = "default:dirt_with_grass", ["param1"] = 28}, {["x"] = 3, ["y"] = 0, ["z"] = 18, ["name"] = "default:dirt_with_grass", ["param1"] = 28}, {["x"] = 3, ["y"] = 0, ["z"] = 19, ["name"] = "default:dirt_with_grass", ["param1"] = 28}, {["x"] = 3, ["y"] = 0, ["z"] = 20, ["name"] = "default:dirt_with_grass", ["param1"] = 28}, {["x"] = 3, ["y"] = 0, ["z"] = 21, ["name"] = "default:dirt_with_grass", ["param1"] = 28}, {["x"] = 3, ["y"] = 0, ["z"] = 22, ["name"] = "default:dirt_with_grass", ["param1"] = 28}, {["x"] = 3, ["y"] = 0, ["z"] = 23, ["name"] = "default:dirt_with_grass", ["param1"] = 28}, {["x"] = 3, ["y"] = 0, ["z"] = 24, ["name"] = "default:dirt_with_grass", ["param1"] = 28}, {["x"] = 3, ["y"] = 0, ["z"] = 25, ["name"] = "default:dirt_with_grass", ["param1"] = 28}, {["x"] = 3, ["y"] = 0, ["z"] = 26, ["name"] = "default:dirt_with_grass", ["param1"] = 28}, {["x"] = 3, ["y"] = 0, ["z"] = 27, ["name"] = "default:dirt_with_grass", ["param1"] = 28}, {["x"] = 3, ["y"] = 0, ["z"] = 28, ["name"] = "default:dirt_with_grass", ["param1"] = 28}, {["x"] = 3, ["y"] = 0, ["z"] = 29, ["name"] = "default:dirt_with_grass", ["param1"] = 28}, {["x"] = 3, ["y"] = 0, ["z"] = 30, ["name"] = "default:dirt_with_grass", ["param1"] = 28}, {["x"] = 3, ["y"] = 0, ["z"] = 31, ["name"] = "default:dirt_with_grass", ["param1"] = 28}, {["x"] = 3, ["y"] = 0, ["z"] = 32, ["name"] = "default:dirt_with_grass", ["param1"] = 28}, {["x"] = 3, ["y"] = 0, ["z"] = 33, ["name"] = "default:dirt_with_grass", ["param1"] = 28}, {["x"] = 3, ["y"] = 0, ["z"] = 34, ["name"] = "default:dirt_with_grass", ["param1"] = 28}, {["x"] = 3, ["y"] = 0, ["z"] = 35, ["name"] = "default:dirt_with_grass", ["param1"] = 28}, {["x"] = 3, ["y"] = 0, ["z"] = 36, ["name"] = "default:dirt_with_grass", ["param1"] = 28}, {["x"] = 3, ["y"] = 0, ["z"] = 37, ["name"] = "default:dirt_with_grass", ["param1"] = 28}, {["x"] = 3, ["y"] = 0, ["z"] = 38, ["name"] = "default:dirt_with_grass", ["param1"] = 28}, {["x"] = 3, ["y"] = 0, ["z"] = 39, ["name"] = "default:dirt_with_grass", ["param1"] = 28}, {["x"] = 3, ["y"] = 0, ["z"] = 40, ["name"] = "default:dirt_with_grass", ["param1"] = 28}, {["x"] = 3, ["y"] = 0, ["z"] = 41, ["name"] = "default:dirt_with_grass", ["param1"] = 28}, {["x"] = 3, ["y"] = 0, ["z"] = 42, ["name"] = "default:dirt_with_grass", ["param1"] = 28}, {["x"] = 3, ["y"] = 0, ["z"] = 43, ["name"] = "default:dirt_with_grass", ["param1"] = 28}, {["x"] = 3, ["y"] = 0, ["z"] = 44, ["name"] = "default:dirt_with_grass", ["param1"] = 28}, {["x"] = 3, ["y"] = 0, ["z"] = 45, ["name"] = "default:dirt_with_grass", ["param1"] = 28}, {["x"] = 3, ["y"] = 0, ["z"] = 46, ["name"] = "default:dirt_with_grass", ["param1"] = 28}, {["x"] = 3, ["y"] = 0, ["z"] = 47, ["name"] = "default:dirt_with_grass", ["param1"] = 28}, {["x"] = 3, ["y"] = 0, ["z"] = 48, ["name"] = "default:dirt_with_grass", ["param1"] = 28}, {["x"] = 3, ["y"] = 0, ["z"] = 49, ["name"] = "default:dirt_with_grass", ["param1"] = 28}, {["x"] = 3, ["y"] = 0, ["z"] = 50, ["name"] = "default:dirt_with_grass", ["param1"] = 28}, {["x"] = 3, ["y"] = 0, ["z"] = 51, ["name"] = "default:dirt_with_grass", ["param1"] = 28}, {["x"] = 3, ["y"] = 0, ["z"] = 52, ["name"] = "default:dirt_with_grass", ["param1"] = 28}, {["x"] = 3, ["y"] = 0, ["z"] = 53, ["name"] = "default:dirt_with_grass", ["param1"] = 28}, {["x"] = 3, ["y"] = 0, ["z"] = 54, ["name"] = "default:dirt_with_grass", ["param1"] = 28}, {["x"] = 3, ["y"] = 1, ["z"] = 2, ["param2"] = 3, ["name"] = "cblocks:stonebrick_brown", ["param1"] = 41}, {["x"] = 3, ["y"] = 1, ["z"] = 3, ["param2"] = 1, ["name"] = "cblocks:stonebrick_brown", ["param1"] = 58}, {["x"] = 3, ["y"] = 1, ["z"] = 4, ["param2"] = 1, ["name"] = "cblocks:stonebrick_brown", ["param1"] = 75}, {["x"] = 3, ["y"] = 1, ["z"] = 5, ["param2"] = 1, ["name"] = "cblocks:stonebrick_brown", ["param1"] = 76}, {["x"] = 3, ["y"] = 1, ["z"] = 6, ["param2"] = 1, ["name"] = "cblocks:stonebrick_brown", ["param1"] = 61}, {["x"] = 3, ["y"] = 1, ["z"] = 7, ["param2"] = 1, ["name"] = "cblocks:stonebrick_brown", ["param1"] = 77}, {["x"] = 3, ["y"] = 1, ["z"] = 8, ["param2"] = 1, ["name"] = "cblocks:stonebrick_brown", ["param1"] = 77}, {["x"] = 3, ["y"] = 1, ["z"] = 9, ["param2"] = 1, ["name"] = "cblocks:stonebrick_brown", ["param1"] = 61}, {["x"] = 3, ["y"] = 1, ["z"] = 10, ["param2"] = 16, ["name"] = "cblocks:slab_wood_black", ["param1"] = 45}, {["x"] = 3, ["y"] = 1, ["z"] = 11, ["param2"] = 16, ["name"] = "cblocks:slab_wood_black", ["param1"] = 45}, {["x"] = 3, ["y"] = 1, ["z"] = 12, ["param2"] = 1, ["name"] = "cblocks:stonebrick_brown", ["param1"] = 61}, {["x"] = 3, ["y"] = 1, ["z"] = 13, ["param2"] = 1, ["name"] = "cblocks:stonebrick_brown", ["param1"] = 77}, {["x"] = 3, ["y"] = 1, ["z"] = 14, ["param2"] = 1, ["name"] = "cblocks:stonebrick_brown", ["param1"] = 77}, {["x"] = 3, ["y"] = 1, ["z"] = 15, ["param2"] = 1, ["name"] = "cblocks:stonebrick_brown", ["param1"] = 61}, {["x"] = 3, ["y"] = 1, ["z"] = 16, ["name"] = "cblocks:stonebrick_brown", ["param1"] = 45}, {["x"] = 3, ["y"] = 1, ["z"] = 17, ["name"] = "cblocks:stonebrick_white", ["param1"] = 61}, {["x"] = 3, ["y"] = 1, ["z"] = 18, ["name"] = "cblocks:stonebrick_white", ["param1"] = 77}, {["x"] = 3, ["y"] = 1, ["z"] = 19, ["name"] = "cblocks:stonebrick_white", ["param1"] = 77}, {["x"] = 3, ["y"] = 1, ["z"] = 20, ["name"] = "cblocks:stonebrick_white", ["param1"] = 61}, {["x"] = 3, ["y"] = 1, ["z"] = 21, ["name"] = "cblocks:stonebrick_white", ["param1"] = 76}, {["x"] = 3, ["y"] = 1, ["z"] = 22, ["name"] = "cblocks:stonebrick_white", ["param1"] = 75},